<robot name = "robot">
    <link name="Link0">
        <inertial>
            <origin xyz="0 0 0.22944824451881468" rpy="0 0 0"/>
            <mass value="1" />
            <inertia ixx="100" ixy="0" ixz="0" iyy="100" iyz="0" izz="100" />
        </inertial>
        <visual>
            <origin xyz="0 0 0.22944824451881468" rpy="0 0 0"/>
            <geometry>
                <box size="1.3259072664850131 1.4401667332089771 0.45889648903762936" />
            </geometry>
            <material name="Blue">
                <color rgba="0.0 0.0 1.0 1.0"/>
            </material>
        </visual>
        <collision>
            <origin xyz="0 0 0.22944824451881468" rpy="0 0 0"/>
            <geometry>
                <box size="1.3259072664850131 1.4401667332089771 0.45889648903762936" />
            </geometry>
        </collision>
    </link>
    <joint name="Link0_Link1" type="revolute">
       <parent link="Link0"/>
       <child  link="Link1"/>
       <origin rpy="0 0 0" xyz="0 0.7200833666044886 0.7551481787076719" />
       <axis xyz="1 0 0"/>
       <limit effort="0.0" lower="-3.14159" upper="3.14159" velocity="0.0"/>
    </joint>
    <link name="Link1">
        <inertial>
            <origin xyz="0 0.7488475042380164 0" rpy="0 0 0"/>
            <mass value="1" />
            <inertia ixx="100" ixy="0" ixz="0" iyy="100" iyz="0" izz="100" />
        </inertial>
        <visual>
            <origin xyz="0 0.7488475042380164 0" rpy="0 0 0"/>
            <geometry>
                <box size="1.1535168223774919 1.4976950084760328 1.5102963574153438" />
            </geometry>
            <material name="Blue">
                <color rgba="0.0 0.0 1.0 1.0"/>
            </material>
        </visual>
        <collision>
            <origin xyz="0 0.7488475042380164 0" rpy="0 0 0"/>
            <geometry>
                <box size="1.1535168223774919 1.4976950084760328 1.5102963574153438" />
            </geometry>
        </collision>
    </link>
    <joint name="Link1_Link2" type="revolute">
       <parent link="Link1"/>
       <child  link="Link2"/>
       <origin rpy="0 0 0" xyz="0 1.4976950084760328 0" />
       <axis xyz="1 0 0"/>
       <limit effort="0.0" lower="-3.14159" upper="3.14159" velocity="0.0"/>
    </joint>
    <link name="Link2">
        <inertial>
            <origin xyz="0 0.8888915646574556 0" rpy="0 0 0"/>
            <mass value="1" />
            <inertia ixx="100" ixy="0" ixz="0" iyy="100" iyz="0" izz="100" />
        </inertial>
        <visual>
            <origin xyz="0 0.8888915646574556 0" rpy="0 0 0"/>
            <geometry>
                <box size="1.7097878194598721 1.7777831293149111 0.23755482938485478" />
            </geometry>
            <material name="Blue">
                <color rgba="0.0 0.0 1.0 1.0"/>
            </material>
        </visual>
        <collision>
            <origin xyz="0 0.8888915646574556 0" rpy="0 0 0"/>
            <geometry>
                <box size="1.7097878194598721 1.7777831293149111 0.23755482938485478" />
            </geometry>
        </collision>
    </link>
</robot>