<robot name = "robot">
    <link name="Link0">
        <inertial>
            <origin xyz="0 0 0.7373219869611578" rpy="0 0 0"/>
            <mass value="1" />
            <inertia ixx="100" ixy="0" ixz="0" iyy="100" iyz="0" izz="100" />
        </inertial>
        <visual>
            <origin xyz="0 0 0.7373219869611578" rpy="0 0 0"/>
            <geometry>
                <box size="1.4673137424944365 0.6017433728464265 1.4746439739223156" />
            </geometry>
            <material name="Blue">
                <color rgba="0.01 0.54 1.0 1.0"/>
            </material>
        </visual>
        <collision>
            <origin xyz="0 0 0.7373219869611578" rpy="0 0 0"/>
            <geometry>
                <box size="1.4673137424944365 0.6017433728464265 1.4746439739223156" />
            </geometry>
        </collision>
    </link>
    <joint name="Link0_Link1" type="revolute">
       <parent link="Link0"/>
       <child  link="Link1"/>
       <origin rpy="0 0 0" xyz="0 0.30087168642321327 0.7373219869611578" />
       <axis xyz="1 0 0"/>
       <limit effort="0.0" lower="-3.14159" upper="3.14159" velocity="0.0"/>
    </joint>
    <link name="Link1">
        <inertial>
            <origin xyz="0 0.4390564913036911 0" rpy="0 0 0"/>
            <mass value="1" />
            <inertia ixx="100" ixy="0" ixz="0" iyy="100" iyz="0" izz="100" />
        </inertial>
        <visual>
            <origin xyz="0 0.4390564913036911 0" rpy="0 0 0"/>
            <geometry>
                <box size="1.4667591108501912 0.8781129826073822 1.2261635513491613" />
            </geometry>
            <material name="Green">
                <color rgba="0.25 0.76 0.50 1.0"/>
            </material>
        </visual>
        <collision>
            <origin xyz="0 0.4390564913036911 0" rpy="0 0 0"/>
            <geometry>
                <box size="1.4667591108501912 0.8781129826073822 1.2261635513491613" />
            </geometry>
        </collision>
    </link>
    <joint name="Link1_Link1XLink0" type="revolute">
       <parent link="Link1"/>
       <child  link="Link1XLink0"/>
       <origin rpy="0 0 0" xyz="0.7333795554250956 0.4390564913036911 0" />
       <axis xyz="1 0 0"/>
       <limit effort="0.0" lower="-3.14159" upper="3.14159" velocity="0.0"/>
    </joint>
    <link name="Link1XLink0">
        <inertial>
            <origin xyz="0.2944520430112263 0 0" rpy="0 0 0"/>
            <mass value="1" />
            <inertia ixx="100" ixy="0" ixz="0" iyy="100" iyz="0" izz="100" />
        </inertial>
        <visual>
            <origin xyz="0.2944520430112263 0 0" rpy="0 0 0"/>
            <geometry>
                <box size="0.5889040860224526 0.8337623649445782 0.5625402022424616" />
            </geometry>
            <material name="Green">
                <color rgba="0.25 0.76 0.50 1.0"/>
            </material>
        </visual>
        <collision>
            <origin xyz="0.2944520430112263 0 0" rpy="0 0 0"/>
            <geometry>
                <box size="0.5889040860224526 0.8337623649445782 0.5625402022424616" />
            </geometry>
        </collision>
    </link>
    <joint name="Link1XLink0_Link1XLink1" type="revolute">
       <parent link="Link1XLink0"/>
       <child  link="Link1XLink1"/>
       <origin rpy="0 0 0" xyz="0.5889040860224526 0 0" />
       <axis xyz="1 0 0"/>
       <limit effort="0.0" lower="-3.14159" upper="3.14159" velocity="0.0"/>
    </joint>
    <link name="Link1XLink1">
        <inertial>
            <origin xyz="0.2944520430112263 0 0" rpy="0 0 0"/>
            <mass value="1" />
            <inertia ixx="100" ixy="0" ixz="0" iyy="100" iyz="0" izz="100" />
        </inertial>
        <visual>
            <origin xyz="0.2944520430112263 0 0" rpy="0 0 0"/>
            <geometry>
                <box size="0.5889040860224526 0.8337623649445782 0.5625402022424616" />
            </geometry>
            <material name="Green">
                <color rgba="0.25 0.76 0.50 1.0"/>
            </material>
        </visual>
        <collision>
            <origin xyz="0.2944520430112263 0 0" rpy="0 0 0"/>
            <geometry>
                <box size="0.5889040860224526 0.8337623649445782 0.5625402022424616" />
            </geometry>
        </collision>
    </link>
    <joint name="Link1_Link2" type="revolute">
       <parent link="Link1"/>
       <child  link="Link2"/>
       <origin rpy="0 0 0" xyz="0 0.8781129826073822 0" />
       <axis xyz="1 0 0"/>
       <limit effort="0.0" lower="-3.14159" upper="3.14159" velocity="0.0"/>
    </joint>
    <link name="Link2">
        <inertial>
            <origin xyz="0 0.2924827132096213 0" rpy="0 0 0"/>
            <mass value="1" />
            <inertia ixx="100" ixy="0" ixz="0" iyy="100" iyz="0" izz="100" />
        </inertial>
        <visual>
            <origin xyz="0 0.2924827132096213 0" rpy="0 0 0"/>
            <geometry>
                <box size="0.8252150030152644 0.5849654264192427 0.9199074025726298" />
            </geometry>
            <material name="Green">
                <color rgba="0.25 0.76 0.50 1.0"/>
            </material>
        </visual>
        <collision>
            <origin xyz="0 0.2924827132096213 0" rpy="0 0 0"/>
            <geometry>
                <box size="0.8252150030152644 0.5849654264192427 0.9199074025726298" />
            </geometry>
        </collision>
    </link>
    <joint name="Link2_Link2ZLink0" type="revolute">
       <parent link="Link2"/>
       <child  link="Link2ZLink0"/>
       <origin rpy="0 0 0" xyz="0 0.2924827132096213 0.4599537012863149" />
       <axis xyz="0 0 1"/>
       <limit effort="0.0" lower="-3.14159" upper="3.14159" velocity="0.0"/>
    </joint>
    <link name="Link2ZLink0">
        <inertial>
            <origin xyz="0 0 0.2717485395963858" rpy="0 0 0"/>
            <mass value="1" />
            <inertia ixx="100" ixy="0" ixz="0" iyy="100" iyz="0" izz="100" />
        </inertial>
        <visual>
            <origin xyz="0 0 0.2717485395963858" rpy="0 0 0"/>
            <geometry>
                <box size="0.665181488470747 0.5849654264192427 0.5434970791927716" />
            </geometry>
            <material name="Blue">
                <color rgba="0.01 0.54 1.0 1.0"/>
            </material>
        </visual>
        <collision>
            <origin xyz="0 0 0.2717485395963858" rpy="0 0 0"/>
            <geometry>
                <box size="0.665181488470747 0.5849654264192427 0.5434970791927716" />
            </geometry>
        </collision>
    </link>
    <joint name="Link2ZLink0_Link2ZLink1" type="revolute">
       <parent link="Link2ZLink0"/>
       <child  link="Link2ZLink1"/>
       <origin rpy="0 0 0" xyz="0 0 0.5434970791927716" />
       <axis xyz="0 0 1"/>
       <limit effort="0.0" lower="-3.14159" upper="3.14159" velocity="0.0"/>
    </joint>
    <link name="Link2ZLink1">
        <inertial>
            <origin xyz="0 0 0.2717485395963858" rpy="0 0 0"/>
            <mass value="1" />
            <inertia ixx="100" ixy="0" ixz="0" iyy="100" iyz="0" izz="100" />
        </inertial>
        <visual>
            <origin xyz="0 0 0.2717485395963858" rpy="0 0 0"/>
            <geometry>
                <box size="0.665181488470747 0.7865983864026465 0.5434970791927716" />
            </geometry>
            <material name="Blue">
                <color rgba="0.01 0.54 1.0 1.0"/>
            </material>
        </visual>
        <collision>
            <origin xyz="0 0 0.2717485395963858" rpy="0 0 0"/>
            <geometry>
                <box size="0.665181488470747 0.7865983864026465 0.5434970791927716" />
            </geometry>
        </collision>
    </link>
    <joint name="Link2_Link3" type="revolute">
       <parent link="Link2"/>
       <child  link="Link3"/>
       <origin rpy="0 0 0" xyz="0 0.5849654264192427 0" />
       <axis xyz="1 0 0"/>
       <limit effort="0.0" lower="-3.14159" upper="3.14159" velocity="0.0"/>
    </joint>
    <link name="Link3">
        <inertial>
            <origin xyz="0 0.3737333064086843 0" rpy="0 0 0"/>
            <mass value="1" />
            <inertia ixx="100" ixy="0" ixz="0" iyy="100" iyz="0" izz="100" />
        </inertial>
        <visual>
            <origin xyz="0 0.3737333064086843 0" rpy="0 0 0"/>
            <geometry>
                <box size="0.5646903749954357 0.7474666128173686 0.7086240024657914" />
            </geometry>
            <material name="Blue">
                <color rgba="0.01 0.54 1.0 1.0"/>
            </material>
        </visual>
        <collision>
            <origin xyz="0 0.3737333064086843 0" rpy="0 0 0"/>
            <geometry>
                <box size="0.5646903749954357 0.7474666128173686 0.7086240024657914" />
            </geometry>
        </collision>
    </link>
    <joint name="Link3_Link3XLink0" type="revolute">
       <parent link="Link3"/>
       <child  link="Link3XLink0"/>
       <origin rpy="0 0 0" xyz="0.28234518749771786 0.3737333064086843 0" />
       <axis xyz="1 0 0"/>
       <limit effort="0.0" lower="-3.14159" upper="3.14159" velocity="0.0"/>
    </joint>
    <link name="Link3XLink0">
        <inertial>
            <origin xyz="0.3809040841286991 0 0" rpy="0 0 0"/>
            <mass value="1" />
            <inertia ixx="100" ixy="0" ixz="0" iyy="100" iyz="0" izz="100" />
        </inertial>
        <visual>
            <origin xyz="0.3809040841286991 0 0" rpy="0 0 0"/>
            <geometry>
                <box size="0.7618081682573982 0.602096749154368 0.9837510440125012" />
            </geometry>
            <material name="Green">
                <color rgba="0.25 0.76 0.50 1.0"/>
            </material>
        </visual>
        <collision>
            <origin xyz="0.3809040841286991 0 0" rpy="0 0 0"/>
            <geometry>
                <box size="0.7618081682573982 0.602096749154368 0.9837510440125012" />
            </geometry>
        </collision>
    </link>
    <joint name="Link3XLink0_Link3XLink1" type="revolute">
       <parent link="Link3XLink0"/>
       <child  link="Link3XLink1"/>
       <origin rpy="0 0 0" xyz="0.7618081682573982 0 0" />
       <axis xyz="1 0 0"/>
       <limit effort="0.0" lower="-3.14159" upper="3.14159" velocity="0.0"/>
    </joint>
    <link name="Link3XLink1">
        <inertial>
            <origin xyz="0.3809040841286991 0 0" rpy="0 0 0"/>
            <mass value="1" />
            <inertia ixx="100" ixy="0" ixz="0" iyy="100" iyz="0" izz="100" />
        </inertial>
        <visual>
            <origin xyz="0.3809040841286991 0 0" rpy="0 0 0"/>
            <geometry>
                <box size="0.7618081682573982 0.602096749154368 0.9837510440125012" />
            </geometry>
            <material name="Green">
                <color rgba="0.25 0.76 0.50 1.0"/>
            </material>
        </visual>
        <collision>
            <origin xyz="0.3809040841286991 0 0" rpy="0 0 0"/>
            <geometry>
                <box size="0.7618081682573982 0.602096749154368 0.9837510440125012" />
            </geometry>
        </collision>
    </link>
    <joint name="Link3XLink1_Link3XLink2" type="revolute">
       <parent link="Link3XLink1"/>
       <child  link="Link3XLink2"/>
       <origin rpy="0 0 0" xyz="0.7618081682573982 0 0" />
       <axis xyz="1 0 0"/>
       <limit effort="0.0" lower="-3.14159" upper="3.14159" velocity="0.0"/>
    </joint>
    <link name="Link3XLink2">
        <inertial>
            <origin xyz="0.3809040841286991 0 0" rpy="0 0 0"/>
            <mass value="1" />
            <inertia ixx="100" ixy="0" ixz="0" iyy="100" iyz="0" izz="100" />
        </inertial>
        <visual>
            <origin xyz="0.3809040841286991 0 0" rpy="0 0 0"/>
            <geometry>
                <box size="0.7618081682573982 0.602096749154368 0.9837510440125012" />
            </geometry>
            <material name="Green">
                <color rgba="0.25 0.76 0.50 1.0"/>
            </material>
        </visual>
        <collision>
            <origin xyz="0.3809040841286991 0 0" rpy="0 0 0"/>
            <geometry>
                <box size="0.7618081682573982 0.602096749154368 0.9837510440125012" />
            </geometry>
        </collision>
    </link>
    <joint name="Link3_Link3MinXLink0" type="revolute">
       <parent link="Link3"/>
       <child  link="Link3MinXLink0"/>
       <origin rpy="0 0 0" xyz="-0.28234518749771786 0.3737333064086843 0" />
       <axis xyz="1 0 0"/>
       <limit effort="0.0" lower="-3.14159" upper="3.14159" velocity="0.0"/>
    </joint>
    <link name="Link3MinXLink0">
        <inertial>
            <origin xyz="-0.4545099911498034 0 0" rpy="0 0 0"/>
            <mass value="1" />
            <inertia ixx="100" ixy="0" ixz="0" iyy="100" iyz="0" izz="100" />
        </inertial>
        <visual>
            <origin xyz="-0.4545099911498034 0 0" rpy="0 0 0"/>
            <geometry>
                <box size="0.9090199822996068 0.6204220288010995 0.8414736955431559" />
            </geometry>
            <material name="Blue">
                <color rgba="0.01 0.54 1.0 1.0"/>
            </material>
        </visual>
        <collision>
            <origin xyz="-0.4545099911498034 0 0" rpy="0 0 0"/>
            <geometry>
                <box size="0.9090199822996068 0.6204220288010995 0.8414736955431559" />
            </geometry>
        </collision>
    </link>
    <joint name="Link3_Link3ZLink0" type="revolute">
       <parent link="Link3"/>
       <child  link="Link3ZLink0"/>
       <origin rpy="0 0 0" xyz="0 0.3737333064086843 0.3543120012328957" />
       <axis xyz="0 0 1"/>
       <limit effort="0.0" lower="-3.14159" upper="3.14159" velocity="0.0"/>
    </joint>
    <link name="Link3ZLink0">
        <inertial>
            <origin xyz="0 0 0.4111869624923815" rpy="0 0 0"/>
            <mass value="1" />
            <inertia ixx="100" ixy="0" ixz="0" iyy="100" iyz="0" izz="100" />
        </inertial>
        <visual>
            <origin xyz="0 0 0.4111869624923815" rpy="0 0 0"/>
            <geometry>
                <box size="0.5282374429066727 0.7120527819933724 0.822373924984763" />
            </geometry>
            <material name="Blue">
                <color rgba="0.01 0.54 1.0 1.0"/>
            </material>
        </visual>
        <collision>
            <origin xyz="0 0 0.4111869624923815" rpy="0 0 0"/>
            <geometry>
                <box size="0.5282374429066727 0.7120527819933724 0.822373924984763" />
            </geometry>
        </collision>
    </link>
    <joint name="Link3ZLink0_Link3ZLink1" type="revolute">
       <parent link="Link3ZLink0"/>
       <child  link="Link3ZLink1"/>
       <origin rpy="0 0 0" xyz="0 0 0.822373924984763" />
       <axis xyz="0 0 1"/>
       <limit effort="0.0" lower="-3.14159" upper="3.14159" velocity="0.0"/>
    </joint>
    <link name="Link3ZLink1">
        <inertial>
            <origin xyz="0 0 0.4111869624923815" rpy="0 0 0"/>
            <mass value="1" />
            <inertia ixx="100" ixy="0" ixz="0" iyy="100" iyz="0" izz="100" />
        </inertial>
        <visual>
            <origin xyz="0 0 0.4111869624923815" rpy="0 0 0"/>
            <geometry>
                <box size="0.5282374429066727 0.7120527819933724 0.822373924984763" />
            </geometry>
            <material name="Green">
                <color rgba="0.25 0.76 0.50 1.0"/>
            </material>
        </visual>
        <collision>
            <origin xyz="0 0 0.4111869624923815" rpy="0 0 0"/>
            <geometry>
                <box size="0.5282374429066727 0.7120527819933724 0.822373924984763" />
            </geometry>
        </collision>
    </link>
    <joint name="Link3_Link4" type="revolute">
       <parent link="Link3"/>
       <child  link="Link4"/>
       <origin rpy="0 0 0" xyz="0 0.7474666128173686 0" />
       <axis xyz="1 0 0"/>
       <limit effort="0.0" lower="-3.14159" upper="3.14159" velocity="0.0"/>
    </joint>
    <link name="Link4">
        <inertial>
            <origin xyz="0 0.30425698042340316 0" rpy="0 0 0"/>
            <mass value="1" />
            <inertia ixx="100" ixy="0" ixz="0" iyy="100" iyz="0" izz="100" />
        </inertial>
        <visual>
            <origin xyz="0 0.30425698042340316 0" rpy="0 0 0"/>
            <geometry>
                <box size="1.4005061972957198 0.6085139608468063 1.3753320353360985" />
            </geometry>
            <material name="Blue">
                <color rgba="0.01 0.54 1.0 1.0"/>
            </material>
        </visual>
        <collision>
            <origin xyz="0 0.30425698042340316 0" rpy="0 0 0"/>
            <geometry>
                <box size="1.4005061972957198 0.6085139608468063 1.3753320353360985" />
            </geometry>
        </collision>
    </link>
    <joint name="Link4_Link4XLink0" type="revolute">
       <parent link="Link4"/>
       <child  link="Link4XLink0"/>
       <origin rpy="0 0 0" xyz="0.7002530986478599 0.30425698042340316 0" />
       <axis xyz="1 0 0"/>
       <limit effort="0.0" lower="-3.14159" upper="3.14159" velocity="0.0"/>
    </joint>
    <link name="Link4XLink0">
        <inertial>
            <origin xyz="0.3985119987825202 0 0" rpy="0 0 0"/>
            <mass value="1" />
            <inertia ixx="100" ixy="0" ixz="0" iyy="100" iyz="0" izz="100" />
        </inertial>
        <visual>
            <origin xyz="0.3985119987825202 0 0" rpy="0 0 0"/>
            <geometry>
                <box size="0.7970239975650404 0.6085139608468063 0.7156851964367557" />
            </geometry>
            <material name="Blue">
                <color rgba="0.01 0.54 1.0 1.0"/>
            </material>
        </visual>
        <collision>
            <origin xyz="0.3985119987825202 0 0" rpy="0 0 0"/>
            <geometry>
                <box size="0.7970239975650404 0.6085139608468063 0.7156851964367557" />
            </geometry>
        </collision>
    </link>
    <joint name="Link4_Link4MinXLink0" type="revolute">
       <parent link="Link4"/>
       <child  link="Link4MinXLink0"/>
       <origin rpy="0 0 0" xyz="-0.7002530986478599 0.30425698042340316 0" />
       <axis xyz="1 0 0"/>
       <limit effort="0.0" lower="-3.14159" upper="3.14159" velocity="0.0"/>
    </joint>
    <link name="Link4MinXLink0">
        <inertial>
            <origin xyz="-0.2652426033767211 0 0" rpy="0 0 0"/>
            <mass value="1" />
            <inertia ixx="100" ixy="0" ixz="0" iyy="100" iyz="0" izz="100" />
        </inertial>
        <visual>
            <origin xyz="-0.2652426033767211 0 0" rpy="0 0 0"/>
            <geometry>
                <box size="0.5304852067534422 0.6085139608468063 0.6673852596207518" />
            </geometry>
            <material name="Green">
                <color rgba="0.25 0.76 0.50 1.0"/>
            </material>
        </visual>
        <collision>
            <origin xyz="-0.2652426033767211 0 0" rpy="0 0 0"/>
            <geometry>
                <box size="0.5304852067534422 0.6085139608468063 0.6673852596207518" />
            </geometry>
        </collision>
    </link>
    <joint name="Link4_Link4ZLink0" type="revolute">
       <parent link="Link4"/>
       <child  link="Link4ZLink0"/>
       <origin rpy="0 0 0" xyz="0 0.30425698042340316 0.6876660176680492" />
       <axis xyz="0 0 1"/>
       <limit effort="0.0" lower="-3.14159" upper="3.14159" velocity="0.0"/>
    </joint>
    <link name="Link4ZLink0">
        <inertial>
            <origin xyz="0 0 0.3590698603329322" rpy="0 0 0"/>
            <mass value="1" />
            <inertia ixx="100" ixy="0" ixz="0" iyy="100" iyz="0" izz="100" />
        </inertial>
        <visual>
            <origin xyz="0 0 0.3590698603329322" rpy="0 0 0"/>
            <geometry>
                <box size="0.8848177128364187 0.6085139608468063 0.7181397206658644" />
            </geometry>
            <material name="Green">
                <color rgba="0.25 0.76 0.50 1.0"/>
            </material>
        </visual>
        <collision>
            <origin xyz="0 0 0.3590698603329322" rpy="0 0 0"/>
            <geometry>
                <box size="0.8848177128364187 0.6085139608468063 0.7181397206658644" />
            </geometry>
        </collision>
    </link>
    <joint name="Link4ZLink0_Link4ZLink1" type="revolute">
       <parent link="Link4ZLink0"/>
       <child  link="Link4ZLink1"/>
       <origin rpy="0 0 0" xyz="0 0 0.7181397206658644" />
       <axis xyz="0 0 1"/>
       <limit effort="0.0" lower="-3.14159" upper="3.14159" velocity="0.0"/>
    </joint>
    <link name="Link4ZLink1">
        <inertial>
            <origin xyz="0 0 0.3590698603329322" rpy="0 0 0"/>
            <mass value="1" />
            <inertia ixx="100" ixy="0" ixz="0" iyy="100" iyz="0" izz="100" />
        </inertial>
        <visual>
            <origin xyz="0 0 0.3590698603329322" rpy="0 0 0"/>
            <geometry>
                <box size="0.8848177128364187 0.8399421967244383 0.7181397206658644" />
            </geometry>
            <material name="Blue">
                <color rgba="0.01 0.54 1.0 1.0"/>
            </material>
        </visual>
        <collision>
            <origin xyz="0 0 0.3590698603329322" rpy="0 0 0"/>
            <geometry>
                <box size="0.8848177128364187 0.8399421967244383 0.7181397206658644" />
            </geometry>
        </collision>
    </link>
    <joint name="Link4_Link5" type="revolute">
       <parent link="Link4"/>
       <child  link="Link5"/>
       <origin rpy="0 0 0" xyz="0 0.6085139608468063 0" />
       <axis xyz="1 0 0"/>
       <limit effort="0.0" lower="-3.14159" upper="3.14159" velocity="0.0"/>
    </joint>
    <link name="Link5">
        <inertial>
            <origin xyz="0 0.46943290705623303 0" rpy="0 0 0"/>
            <mass value="1" />
            <inertia ixx="100" ixy="0" ixz="0" iyy="100" iyz="0" izz="100" />
        </inertial>
        <visual>
            <origin xyz="0 0.46943290705623303 0" rpy="0 0 0"/>
            <geometry>
                <box size="1.298093002316262 0.9388658141124661 0.9663934357247247" />
            </geometry>
            <material name="Blue">
                <color rgba="0.01 0.54 1.0 1.0"/>
            </material>
        </visual>
        <collision>
            <origin xyz="0 0.46943290705623303 0" rpy="0 0 0"/>
            <geometry>
                <box size="1.298093002316262 0.9388658141124661 0.9663934357247247" />
            </geometry>
        </collision>
    </link>
    <joint name="Link5_Link5XLink0" type="revolute">
       <parent link="Link5"/>
       <child  link="Link5XLink0"/>
       <origin rpy="0 0 0" xyz="0.649046501158131 0.46943290705623303 0" />
       <axis xyz="1 0 0"/>
       <limit effort="0.0" lower="-3.14159" upper="3.14159" velocity="0.0"/>
    </joint>
    <link name="Link5XLink0">
        <inertial>
            <origin xyz="0.38331781334675996 0 0" rpy="0 0 0"/>
            <mass value="1" />
            <inertia ixx="100" ixy="0" ixz="0" iyy="100" iyz="0" izz="100" />
        </inertial>
        <visual>
            <origin xyz="0.38331781334675996 0 0" rpy="0 0 0"/>
            <geometry>
                <box size="0.7666356266935199 0.8909402156274544 0.5995804216090428" />
            </geometry>
            <material name="Green">
                <color rgba="0.25 0.76 0.50 1.0"/>
            </material>
        </visual>
        <collision>
            <origin xyz="0.38331781334675996 0 0" rpy="0 0 0"/>
            <geometry>
                <box size="0.7666356266935199 0.8909402156274544 0.5995804216090428" />
            </geometry>
        </collision>
    </link>
    <joint name="Link5XLink0_Link5XLink1" type="revolute">
       <parent link="Link5XLink0"/>
       <child  link="Link5XLink1"/>
       <origin rpy="0 0 0" xyz="0.7666356266935199 0 0" />
       <axis xyz="1 0 0"/>
       <limit effort="0.0" lower="-3.14159" upper="3.14159" velocity="0.0"/>
    </joint>
    <link name="Link5XLink1">
        <inertial>
            <origin xyz="0.38331781334675996 0 0" rpy="0 0 0"/>
            <mass value="1" />
            <inertia ixx="100" ixy="0" ixz="0" iyy="100" iyz="0" izz="100" />
        </inertial>
        <visual>
            <origin xyz="0.38331781334675996 0 0" rpy="0 0 0"/>
            <geometry>
                <box size="0.7666356266935199 0.8909402156274544 0.5995804216090428" />
            </geometry>
            <material name="Blue">
                <color rgba="0.01 0.54 1.0 1.0"/>
            </material>
        </visual>
        <collision>
            <origin xyz="0.38331781334675996 0 0" rpy="0 0 0"/>
            <geometry>
                <box size="0.7666356266935199 0.8909402156274544 0.5995804216090428" />
            </geometry>
        </collision>
    </link>
    <joint name="Link5XLink1_Link5XLink2" type="revolute">
       <parent link="Link5XLink1"/>
       <child  link="Link5XLink2"/>
       <origin rpy="0 0 0" xyz="0.7666356266935199 0 0" />
       <axis xyz="1 0 0"/>
       <limit effort="0.0" lower="-3.14159" upper="3.14159" velocity="0.0"/>
    </joint>
    <link name="Link5XLink2">
        <inertial>
            <origin xyz="0.38331781334675996 0 0" rpy="0 0 0"/>
            <mass value="1" />
            <inertia ixx="100" ixy="0" ixz="0" iyy="100" iyz="0" izz="100" />
        </inertial>
        <visual>
            <origin xyz="0.38331781334675996 0 0" rpy="0 0 0"/>
            <geometry>
                <box size="0.7666356266935199 0.8909402156274544 0.5995804216090428" />
            </geometry>
            <material name="Blue">
                <color rgba="0.01 0.54 1.0 1.0"/>
            </material>
        </visual>
        <collision>
            <origin xyz="0.38331781334675996 0 0" rpy="0 0 0"/>
            <geometry>
                <box size="0.7666356266935199 0.8909402156274544 0.5995804216090428" />
            </geometry>
        </collision>
    </link>
    <joint name="Link5_Link5MinXLink0" type="revolute">
       <parent link="Link5"/>
       <child  link="Link5MinXLink0"/>
       <origin rpy="0 0 0" xyz="-0.649046501158131 0.46943290705623303 0" />
       <axis xyz="1 0 0"/>
       <limit effort="0.0" lower="-3.14159" upper="3.14159" velocity="0.0"/>
    </joint>
    <link name="Link5MinXLink0">
        <inertial>
            <origin xyz="-0.4029486122174397 0 0" rpy="0 0 0"/>
            <mass value="1" />
            <inertia ixx="100" ixy="0" ixz="0" iyy="100" iyz="0" izz="100" />
        </inertial>
        <visual>
            <origin xyz="-0.4029486122174397 0 0" rpy="0 0 0"/>
            <geometry>
                <box size="0.8058972244348794 0.624845408685738 0.7345735297027745" />
            </geometry>
            <material name="Green">
                <color rgba="0.25 0.76 0.50 1.0"/>
            </material>
        </visual>
        <collision>
            <origin xyz="-0.4029486122174397 0 0" rpy="0 0 0"/>
            <geometry>
                <box size="0.8058972244348794 0.624845408685738 0.7345735297027745" />
            </geometry>
        </collision>
    </link>
    <joint name="Link5MinXLink0_Link5MinXLink1" type="revolute">
       <parent link="Link5MinXLink0"/>
       <child  link="Link5MinXLink1"/>
       <origin rpy="0 0 0" xyz="-0.8058972244348794 0 0" />
       <axis xyz="1 0 0"/>
       <limit effort="0.0" lower="-3.14159" upper="3.14159" velocity="0.0"/>
    </joint>
    <link name="Link5MinXLink1">
        <inertial>
            <origin xyz="-0.4029486122174397 0 0" rpy="0 0 0"/>
            <mass value="1" />
            <inertia ixx="100" ixy="0" ixz="0" iyy="100" iyz="0" izz="100" />
        </inertial>
        <visual>
            <origin xyz="-0.4029486122174397 0 0" rpy="0 0 0"/>
            <geometry>
                <box size="0.8058972244348794 0.624845408685738 0.7345735297027745" />
            </geometry>
            <material name="Blue">
                <color rgba="0.01 0.54 1.0 1.0"/>
            </material>
        </visual>
        <collision>
            <origin xyz="-0.4029486122174397 0 0" rpy="0 0 0"/>
            <geometry>
                <box size="0.8058972244348794 0.624845408685738 0.7345735297027745" />
            </geometry>
        </collision>
    </link>
    <joint name="Link5MinXLink1_Link5MinXLink2" type="revolute">
       <parent link="Link5MinXLink1"/>
       <child  link="Link5MinXLink2"/>
       <origin rpy="0 0 0" xyz="-0.8058972244348794 0 0" />
       <axis xyz="1 0 0"/>
       <limit effort="0.0" lower="-3.14159" upper="3.14159" velocity="0.0"/>
    </joint>
    <link name="Link5MinXLink2">
        <inertial>
            <origin xyz="-0.4029486122174397 0 0" rpy="0 0 0"/>
            <mass value="1" />
            <inertia ixx="100" ixy="0" ixz="0" iyy="100" iyz="0" izz="100" />
        </inertial>
        <visual>
            <origin xyz="-0.4029486122174397 0 0" rpy="0 0 0"/>
            <geometry>
                <box size="0.8058972244348794 0.624845408685738 0.7345735297027745" />
            </geometry>
            <material name="Green">
                <color rgba="0.25 0.76 0.50 1.0"/>
            </material>
        </visual>
        <collision>
            <origin xyz="-0.4029486122174397 0 0" rpy="0 0 0"/>
            <geometry>
                <box size="0.8058972244348794 0.624845408685738 0.7345735297027745" />
            </geometry>
        </collision>
    </link>
    <joint name="Link5_Link5ZLink0" type="revolute">
       <parent link="Link5"/>
       <child  link="Link5ZLink0"/>
       <origin rpy="0 0 0" xyz="0 0.46943290705623303 0.48319671786236235" />
       <axis xyz="0 0 1"/>
       <limit effort="0.0" lower="-3.14159" upper="3.14159" velocity="0.0"/>
    </joint>
    <link name="Link5ZLink0">
        <inertial>
            <origin xyz="0 0 0.4353279159858843" rpy="0 0 0"/>
            <mass value="1" />
            <inertia ixx="100" ixy="0" ixz="0" iyy="100" iyz="0" izz="100" />
        </inertial>
        <visual>
            <origin xyz="0 0 0.4353279159858843" rpy="0 0 0"/>
            <geometry>
                <box size="0.6789275874989416 0.5085989123918809 0.8706558319717685" />
            </geometry>
            <material name="Blue">
                <color rgba="0.01 0.54 1.0 1.0"/>
            </material>
        </visual>
        <collision>
            <origin xyz="0 0 0.4353279159858843" rpy="0 0 0"/>
            <geometry>
                <box size="0.6789275874989416 0.5085989123918809 0.8706558319717685" />
            </geometry>
        </collision>
    </link>
</robot>