<robot name = "robot">
    <link name="Link0">
        <inertial>
            <origin xyz="0 0 0.5698805605476875" rpy="0 0 0"/>
            <mass value="1" />
            <inertia ixx="100" ixy="0" ixz="0" iyy="100" iyz="0" izz="100" />
        </inertial>
        <visual>
            <origin xyz="0 0 0.5698805605476875" rpy="0 0 0"/>
            <geometry>
                <box size="0.7319036431060393 0.6133605015786847 1.139761121095375" />
            </geometry>
            <material name="Blue">
                <color rgba="0.0 0.0 1.0 1.0"/>
            </material>
        </visual>
        <collision>
            <origin xyz="0 0 0.5698805605476875" rpy="0 0 0"/>
            <geometry>
                <box size="0.7319036431060393 0.6133605015786847 1.139761121095375" />
            </geometry>
        </collision>
    </link>
    <joint name="Link0_Link1" type="revolute">
       <parent link="Link0"/>
       <child  link="Link1"/>
       <origin rpy="0 0 0" xyz="0 0.30668025078934236 0.6813376675078882" />
       <axis xyz="1 0 0"/>
       <limit effort="0.0" lower="-3.14159" upper="3.14159" velocity="0.0"/>
    </joint>
    <link name="Link1">
        <inertial>
            <origin xyz="0 0.26586621310981307 0" rpy="0 0 0"/>
            <mass value="1" />
            <inertia ixx="100" ixy="0" ixz="0" iyy="100" iyz="0" izz="100" />
        </inertial>
        <visual>
            <origin xyz="0 0.26586621310981307 0" rpy="0 0 0"/>
            <geometry>
                <box size="0.8247768043628712 0.5317324262196261 1.3626753350157763" />
            </geometry>
            <material name="Green">
                <color rgba="0.0 1.0 0.0 1.0"/>
            </material>
        </visual>
        <collision>
            <origin xyz="0 0.26586621310981307 0" rpy="0 0 0"/>
            <geometry>
                <box size="0.8247768043628712 0.5317324262196261 1.3626753350157763" />
            </geometry>
        </collision>
    </link>
    <joint name="Link1_Link1XLink0" type="revolute">
       <parent link="Link1"/>
       <child  link="Link1XLink0"/>
       <origin rpy="0 0 0" xyz="0.4123884021814356 0.26586621310981307 0" />
       <axis xyz="1 0 0"/>
       <limit effort="0.0" lower="-3.14159" upper="3.14159" velocity="0.0"/>
    </joint>
    <link name="Link1XLink0">
        <inertial>
            <origin xyz="0.46284483653021014 0 0" rpy="0 0 0"/>
            <mass value="1" />
            <inertia ixx="100" ixy="0" ixz="0" iyy="100" iyz="0" izz="100" />
        </inertial>
        <visual>
            <origin xyz="0.46284483653021014 0 0" rpy="0 0 0"/>
            <geometry>
                <box size="0.9256896730604203 0.5317324262196261 0.9930063773085074" />
            </geometry>
            <material name="Green">
                <color rgba="0.0 1.0 0.0 1.0"/>
            </material>
        </visual>
        <collision>
            <origin xyz="0.46284483653021014 0 0" rpy="0 0 0"/>
            <geometry>
                <box size="0.9256896730604203 0.5317324262196261 0.9930063773085074" />
            </geometry>
        </collision>
    </link>
    <joint name="Link1_Link1ZLink0" type="revolute">
       <parent link="Link1"/>
       <child  link="Link1ZLink0"/>
       <origin rpy="0 0 0" xyz="0 -0.26586621310981307 [0.56988056 0.68133767 0.40105773 0.66240372 0.51845138 0.36966321
 0.50366993]" />
       <axis xyz="0 0 1"/>
       <limit effort="0.0" lower="-3.14159" upper="3.14159" velocity="0.0"/>
    </joint>
    <link name="Link1ZLink0">
        <inertial>
            <origin xyz="0 0 0.2756387538581069" rpy="0 0 0"/>
            <mass value="1" />
            <inertia ixx="100" ixy="0" ixz="0" iyy="100" iyz="0" izz="100" />
        </inertial>
        <visual>
            <origin xyz="0 0 0.2756387538581069" rpy="0 0 0"/>
            <geometry>
                <box size="0.8247768043628712 0.5317324262196261 0.5512775077162138" />
            </geometry>
            <material name="Green">
                <color rgba="0.0 1.0 0.0 1.0"/>
            </material>
        </visual>
        <collision>
            <origin xyz="0 0 0.2756387538581069" rpy="0 0 0"/>
            <geometry>
                <box size="0.8247768043628712 0.5317324262196261 0.5512775077162138" />
            </geometry>
        </collision>
    </link>
    <joint name="Link1_Link2" type="revolute">
       <parent link="Link1"/>
       <child  link="Link2"/>
       <origin rpy="0 0 0" xyz="0 0.5317324262196261 0" />
       <axis xyz="1 0 0"/>
       <limit effort="0.0" lower="-3.14159" upper="3.14159" velocity="0.0"/>
    </joint>
    <link name="Link2">
        <inertial>
            <origin xyz="0 0.3232064822405811 0" rpy="0 0 0"/>
            <mass value="1" />
            <inertia ixx="100" ixy="0" ixz="0" iyy="100" iyz="0" izz="100" />
        </inertial>
        <visual>
            <origin xyz="0 0.3232064822405811 0" rpy="0 0 0"/>
            <geometry>
                <box size="0.8285636544242897 0.6464129644811623 0.8021154688836524" />
            </geometry>
            <material name="Green">
                <color rgba="0.0 1.0 0.0 1.0"/>
            </material>
        </visual>
        <collision>
            <origin xyz="0 0.3232064822405811 0" rpy="0 0 0"/>
            <geometry>
                <box size="0.8285636544242897 0.6464129644811623 0.8021154688836524" />
            </geometry>
        </collision>
    </link>
    <joint name="Link2_Link2XLink0" type="revolute">
       <parent link="Link2"/>
       <child  link="Link2XLink0"/>
       <origin rpy="0 0 0" xyz="0.41428182721214485 0.3232064822405811 0" />
       <axis xyz="1 0 0"/>
       <limit effort="0.0" lower="-3.14159" upper="3.14159" velocity="0.0"/>
    </joint>
    <link name="Link2XLink0">
        <inertial>
            <origin xyz="0.3480321645756267 0 0" rpy="0 0 0"/>
            <mass value="1" />
            <inertia ixx="100" ixy="0" ixz="0" iyy="100" iyz="0" izz="100" />
        </inertial>
        <visual>
            <origin xyz="0.3480321645756267 0 0" rpy="0 0 0"/>
            <geometry>
                <box size="0.6960643291512534 0.6464129644811623 0.5066951223386589" />
            </geometry>
            <material name="Green">
                <color rgba="0.0 1.0 0.0 1.0"/>
            </material>
        </visual>
        <collision>
            <origin xyz="0.3480321645756267 0 0" rpy="0 0 0"/>
            <geometry>
                <box size="0.6960643291512534 0.6464129644811623 0.5066951223386589" />
            </geometry>
        </collision>
    </link>
    <joint name="Link2_Link2MinXLink0" type="revolute">
       <parent link="Link2"/>
       <child  link="Link2MinXLink0"/>
       <origin rpy="0 0 0" xyz="-0.41428182721214485 0.3232064822405811 0" />
       <axis xyz="1 0 0"/>
       <limit effort="0.0" lower="-3.14159" upper="3.14159" velocity="0.0"/>
    </joint>
    <link name="Link2MinXLink0">
        <inertial>
            <origin xyz="-0.3315876989189823 0 0" rpy="0 0 0"/>
            <mass value="1" />
            <inertia ixx="100" ixy="0" ixz="0" iyy="100" iyz="0" izz="100" />
        </inertial>
        <visual>
            <origin xyz="-0.3315876989189823 0 0" rpy="0 0 0"/>
            <geometry>
                <box size="0.6631753978379646 0.5114330167748792 0.779141133863006" />
            </geometry>
            <material name="Blue">
                <color rgba="0.0 0.0 1.0 1.0"/>
            </material>
        </visual>
        <collision>
            <origin xyz="-0.3315876989189823 0 0" rpy="0 0 0"/>
            <geometry>
                <box size="0.6631753978379646 0.5114330167748792 0.779141133863006" />
            </geometry>
        </collision>
    </link>
    <joint name="Link2_Link3" type="revolute">
       <parent link="Link2"/>
       <child  link="Link3"/>
       <origin rpy="0 0 0" xyz="0 0.6464129644811623 0" />
       <axis xyz="1 0 0"/>
       <limit effort="0.0" lower="-3.14159" upper="3.14159" velocity="0.0"/>
    </joint>
    <link name="Link3">
        <inertial>
            <origin xyz="0 0.40958210388454214 0" rpy="0 0 0"/>
            <mass value="1" />
            <inertia ixx="100" ixy="0" ixz="0" iyy="100" iyz="0" izz="100" />
        </inertial>
        <visual>
            <origin xyz="0 0.40958210388454214 0" rpy="0 0 0"/>
            <geometry>
                <box size="0.9868199680814971 0.8191642077690843 1.3248074473085074" />
            </geometry>
            <material name="Green">
                <color rgba="0.0 1.0 0.0 1.0"/>
            </material>
        </visual>
        <collision>
            <origin xyz="0 0.40958210388454214 0" rpy="0 0 0"/>
            <geometry>
                <box size="0.9868199680814971 0.8191642077690843 1.3248074473085074" />
            </geometry>
        </collision>
    </link>
    <joint name="Link3_Link3XLink0" type="revolute">
       <parent link="Link3"/>
       <child  link="Link3XLink0"/>
       <origin rpy="0 0 0" xyz="0.49340998404074854 0.40958210388454214 0" />
       <axis xyz="1 0 0"/>
       <limit effort="0.0" lower="-3.14159" upper="3.14159" velocity="0.0"/>
    </joint>
    <link name="Link3XLink0">
        <inertial>
            <origin xyz="0.34743250389047203 0 0" rpy="0 0 0"/>
            <mass value="1" />
            <inertia ixx="100" ixy="0" ixz="0" iyy="100" iyz="0" izz="100" />
        </inertial>
        <visual>
            <origin xyz="0.34743250389047203 0 0" rpy="0 0 0"/>
            <geometry>
                <box size="0.6948650077809441 0.8191642077690843 0.9134016023189478" />
            </geometry>
            <material name="Blue">
                <color rgba="0.0 0.0 1.0 1.0"/>
            </material>
        </visual>
        <collision>
            <origin xyz="0.34743250389047203 0 0" rpy="0 0 0"/>
            <geometry>
                <box size="0.6948650077809441 0.8191642077690843 0.9134016023189478" />
            </geometry>
        </collision>
    </link>
    <joint name="Link3XLink0_Link3XLink1" type="revolute">
       <parent link="Link3XLink0"/>
       <child  link="Link3XLink1"/>
       <origin rpy="0 0 0" xyz="0.6948650077809441 0 0" />
       <axis xyz="1 0 0"/>
       <limit effort="0.0" lower="-3.14159" upper="3.14159" velocity="0.0"/>
    </joint>
    <link name="Link3XLink1">
        <inertial>
            <origin xyz="0.4314833853491169 0 0" rpy="0 0 0"/>
            <mass value="1" />
            <inertia ixx="100" ixy="0" ixz="0" iyy="100" iyz="0" izz="100" />
        </inertial>
        <visual>
            <origin xyz="0.4314833853491169 0 0" rpy="0 0 0"/>
            <geometry>
                <box size="0.8629667706982338 0.5458716264817558 0.8272876092753887" />
            </geometry>
            <material name="Blue">
                <color rgba="0.0 0.0 1.0 1.0"/>
            </material>
        </visual>
        <collision>
            <origin xyz="0.4314833853491169 0 0" rpy="0 0 0"/>
            <geometry>
                <box size="0.8629667706982338 0.5458716264817558 0.8272876092753887" />
            </geometry>
        </collision>
    </link>
    <joint name="Link3XLink1_Link3XLink2" type="revolute">
       <parent link="Link3XLink1"/>
       <child  link="Link3XLink2"/>
       <origin rpy="0 0 0" xyz="0.8629667706982338 0 0" />
       <axis xyz="1 0 0"/>
       <limit effort="0.0" lower="-3.14159" upper="3.14159" velocity="0.0"/>
    </joint>
    <link name="Link3XLink2">
        <inertial>
            <origin xyz="0.48710194894344516 0 0" rpy="0 0 0"/>
            <mass value="1" />
            <inertia ixx="100" ixy="0" ixz="0" iyy="100" iyz="0" izz="100" />
        </inertial>
        <visual>
            <origin xyz="0.48710194894344516 0 0" rpy="0 0 0"/>
            <geometry>
                <box size="0.9742038978868903 0.5458716264817558 0.5700688060198874" />
            </geometry>
            <material name="Blue">
                <color rgba="0.0 0.0 1.0 1.0"/>
            </material>
        </visual>
        <collision>
            <origin xyz="0.48710194894344516 0 0" rpy="0 0 0"/>
            <geometry>
                <box size="0.9742038978868903 0.5458716264817558 0.5700688060198874" />
            </geometry>
        </collision>
    </link>
    <joint name="Link3_Link3MinXLink0" type="revolute">
       <parent link="Link3"/>
       <child  link="Link3MinXLink0"/>
       <origin rpy="0 0 0" xyz="-0.49340998404074854 0.40958210388454214 0" />
       <axis xyz="1 0 0"/>
       <limit effort="0.0" lower="-3.14159" upper="3.14159" velocity="0.0"/>
    </joint>
    <link name="Link3MinXLink0">
        <inertial>
            <origin xyz="-0.4342266167429105 0 0" rpy="0 0 0"/>
            <mass value="1" />
            <inertia ixx="100" ixy="0" ixz="0" iyy="100" iyz="0" izz="100" />
        </inertial>
        <visual>
            <origin xyz="-0.4342266167429105 0 0" rpy="0 0 0"/>
            <geometry>
                <box size="0.868453233485821 0.8191642077690843 0.9930939669662389" />
            </geometry>
            <material name="Green">
                <color rgba="0.0 1.0 0.0 1.0"/>
            </material>
        </visual>
        <collision>
            <origin xyz="-0.4342266167429105 0 0" rpy="0 0 0"/>
            <geometry>
                <box size="0.868453233485821 0.8191642077690843 0.9930939669662389" />
            </geometry>
        </collision>
    </link>
    <joint name="Link3MinXLink0_Link3MinXLink1" type="revolute">
       <parent link="Link3MinXLink0"/>
       <child  link="Link3MinXLink1"/>
       <origin rpy="0 0 0" xyz="-0.868453233485821 0 0" />
       <axis xyz="1 0 0"/>
       <limit effort="0.0" lower="-3.14159" upper="3.14159" velocity="0.0"/>
    </joint>
    <link name="Link3MinXLink1">
        <inertial>
            <origin xyz="-0.27178664749098064 0 0" rpy="0 0 0"/>
            <mass value="1" />
            <inertia ixx="100" ixy="0" ixz="0" iyy="100" iyz="0" izz="100" />
        </inertial>
        <visual>
            <origin xyz="-0.27178664749098064 0 0" rpy="0 0 0"/>
            <geometry>
                <box size="0.5435732949819613 0.7261430293893296 0.5721992542783162" />
            </geometry>
            <material name="Green">
                <color rgba="0.0 1.0 0.0 1.0"/>
            </material>
        </visual>
        <collision>
            <origin xyz="-0.27178664749098064 0 0" rpy="0 0 0"/>
            <geometry>
                <box size="0.5435732949819613 0.7261430293893296 0.5721992542783162" />
            </geometry>
        </collision>
    </link>
    <joint name="Link3_Link3ZLink0" type="revolute">
       <parent link="Link3"/>
       <child  link="Link3ZLink0"/>
       <origin rpy="0 0 0" xyz="0 -0.40958210388454214 [0.56988056 0.68133767 0.40105773 0.66240372 0.51845138 0.36966321
 0.50366993]" />
       <axis xyz="0 0 1"/>
       <limit effort="0.0" lower="-3.14159" upper="3.14159" velocity="0.0"/>
    </joint>
    <link name="Link3ZLink0">
        <inertial>
            <origin xyz="0 0 0.4105703812945253" rpy="0 0 0"/>
            <mass value="1" />
            <inertia ixx="100" ixy="0" ixz="0" iyy="100" iyz="0" izz="100" />
        </inertial>
        <visual>
            <origin xyz="0 0 0.4105703812945253" rpy="0 0 0"/>
            <geometry>
                <box size="0.9674333958315764 0.8191642077690843 0.8211407625890506" />
            </geometry>
            <material name="Green">
                <color rgba="0.0 1.0 0.0 1.0"/>
            </material>
        </visual>
        <collision>
            <origin xyz="0 0 0.4105703812945253" rpy="0 0 0"/>
            <geometry>
                <box size="0.9674333958315764 0.8191642077690843 0.8211407625890506" />
            </geometry>
        </collision>
    </link>
    <joint name="Link3ZLink0_Link3ZLink1" type="revolute">
       <parent link="Link3ZLink0"/>
       <child  link="Link3ZLink1"/>
       <origin rpy="0 0 0" xyz="0 0 0.8211407625890506" />
       <axis xyz="0 0 1"/>
       <limit effort="0.0" lower="-3.14159" upper="3.14159" velocity="0.0"/>
    </joint>
    <link name="Link3ZLink1">
        <inertial>
            <origin xyz="0 0 0.47502442959475955" rpy="0 0 0"/>
            <mass value="1" />
            <inertia ixx="100" ixy="0" ixz="0" iyy="100" iyz="0" izz="100" />
        </inertial>
        <visual>
            <origin xyz="0 0 0.47502442959475955" rpy="0 0 0"/>
            <geometry>
                <box size="0.9432582294312156 0.7472784743989974 0.9500488591895191" />
            </geometry>
            <material name="Blue">
                <color rgba="0.0 0.0 1.0 1.0"/>
            </material>
        </visual>
        <collision>
            <origin xyz="0 0 0.47502442959475955" rpy="0 0 0"/>
            <geometry>
                <box size="0.9432582294312156 0.7472784743989974 0.9500488591895191" />
            </geometry>
        </collision>
    </link>
    <joint name="Link3_Link4" type="revolute">
       <parent link="Link3"/>
       <child  link="Link4"/>
       <origin rpy="0 0 0" xyz="0 0.8191642077690843 0" />
       <axis xyz="1 0 0"/>
       <limit effort="0.0" lower="-3.14159" upper="3.14159" velocity="0.0"/>
    </joint>
    <link name="Link4">
        <inertial>
            <origin xyz="0 0.28622504278677896 0" rpy="0 0 0"/>
            <mass value="1" />
            <inertia ixx="100" ixy="0" ixz="0" iyy="100" iyz="0" izz="100" />
        </inertial>
        <visual>
            <origin xyz="0 0.28622504278677896 0" rpy="0 0 0"/>
            <geometry>
                <box size="0.8044207059996972 0.5724500855735579 1.0369027695656712" />
            </geometry>
            <material name="Green">
                <color rgba="0.0 1.0 0.0 1.0"/>
            </material>
        </visual>
        <collision>
            <origin xyz="0 0.28622504278677896 0" rpy="0 0 0"/>
            <geometry>
                <box size="0.8044207059996972 0.5724500855735579 1.0369027695656712" />
            </geometry>
        </collision>
    </link>
    <joint name="Link4_Link4XLink0" type="revolute">
       <parent link="Link4"/>
       <child  link="Link4XLink0"/>
       <origin rpy="0 0 0" xyz="0.4022103529998486 0.28622504278677896 0" />
       <axis xyz="1 0 0"/>
       <limit effort="0.0" lower="-3.14159" upper="3.14159" velocity="0.0"/>
    </joint>
    <link name="Link4XLink0">
        <inertial>
            <origin xyz="0.30807065116986243 0 0" rpy="0 0 0"/>
            <mass value="1" />
            <inertia ixx="100" ixy="0" ixz="0" iyy="100" iyz="0" izz="100" />
        </inertial>
        <visual>
            <origin xyz="0.30807065116986243 0 0" rpy="0 0 0"/>
            <geometry>
                <box size="0.6161413023397249 0.535755085958094 0.7586855932602034" />
            </geometry>
            <material name="Blue">
                <color rgba="0.0 0.0 1.0 1.0"/>
            </material>
        </visual>
        <collision>
            <origin xyz="0.30807065116986243 0 0" rpy="0 0 0"/>
            <geometry>
                <box size="0.6161413023397249 0.535755085958094 0.7586855932602034" />
            </geometry>
        </collision>
    </link>
    <joint name="Link4_Link4MinXLink0" type="revolute">
       <parent link="Link4"/>
       <child  link="Link4MinXLink0"/>
       <origin rpy="0 0 0" xyz="-0.4022103529998486 0.28622504278677896 0" />
       <axis xyz="1 0 0"/>
       <limit effort="0.0" lower="-3.14159" upper="3.14159" velocity="0.0"/>
    </joint>
    <link name="Link4MinXLink0">
        <inertial>
            <origin xyz="-0.2851098099219177 0 0" rpy="0 0 0"/>
            <mass value="1" />
            <inertia ixx="100" ixy="0" ixz="0" iyy="100" iyz="0" izz="100" />
        </inertial>
        <visual>
            <origin xyz="-0.2851098099219177 0 0" rpy="0 0 0"/>
            <geometry>
                <box size="0.5702196198438354 0.5724500855735579 0.7882207813729096" />
            </geometry>
            <material name="Blue">
                <color rgba="0.0 0.0 1.0 1.0"/>
            </material>
        </visual>
        <collision>
            <origin xyz="-0.2851098099219177 0 0" rpy="0 0 0"/>
            <geometry>
                <box size="0.5702196198438354 0.5724500855735579 0.7882207813729096" />
            </geometry>
        </collision>
    </link>
    <joint name="Link4MinXLink0_Link4MinXLink1" type="revolute">
       <parent link="Link4MinXLink0"/>
       <child  link="Link4MinXLink1"/>
       <origin rpy="0 0 0" xyz="-0.5702196198438354 0 0" />
       <axis xyz="1 0 0"/>
       <limit effort="0.0" lower="-3.14159" upper="3.14159" velocity="0.0"/>
    </joint>
    <link name="Link4MinXLink1">
        <inertial>
            <origin xyz="-0.40854299112977044 0 0" rpy="0 0 0"/>
            <mass value="1" />
            <inertia ixx="100" ixy="0" ixz="0" iyy="100" iyz="0" izz="100" />
        </inertial>
        <visual>
            <origin xyz="-0.40854299112977044 0 0" rpy="0 0 0"/>
            <geometry>
                <box size="0.8170859822595409 0.6340604150859717 0.6467978058543227" />
            </geometry>
            <material name="Green">
                <color rgba="0.0 1.0 0.0 1.0"/>
            </material>
        </visual>
        <collision>
            <origin xyz="-0.40854299112977044 0 0" rpy="0 0 0"/>
            <geometry>
                <box size="0.8170859822595409 0.6340604150859717 0.6467978058543227" />
            </geometry>
        </collision>
    </link>
    <joint name="Link4_Link4ZLink0" type="revolute">
       <parent link="Link4"/>
       <child  link="Link4ZLink0"/>
       <origin rpy="0 0 0" xyz="0 -0.28622504278677896 [0.56988056 0.68133767 0.40105773 0.66240372 0.51845138 0.36966321
 0.50366993]" />
       <axis xyz="0 0 1"/>
       <limit effort="0.0" lower="-3.14159" upper="3.14159" velocity="0.0"/>
    </joint>
    <link name="Link4ZLink0">
        <inertial>
            <origin xyz="0 0 0.34526627754517614" rpy="0 0 0"/>
            <mass value="1" />
            <inertia ixx="100" ixy="0" ixz="0" iyy="100" iyz="0" izz="100" />
        </inertial>
        <visual>
            <origin xyz="0 0 0.34526627754517614" rpy="0 0 0"/>
            <geometry>
                <box size="0.6669519014242027 0.5724500855735579 0.6905325550903523" />
            </geometry>
            <material name="Blue">
                <color rgba="0.0 0.0 1.0 1.0"/>
            </material>
        </visual>
        <collision>
            <origin xyz="0 0 0.34526627754517614" rpy="0 0 0"/>
            <geometry>
                <box size="0.6669519014242027 0.5724500855735579 0.6905325550903523" />
            </geometry>
        </collision>
    </link>
    <joint name="Link4_Link5" type="revolute">
       <parent link="Link4"/>
       <child  link="Link5"/>
       <origin rpy="0 0 0" xyz="0 0.5724500855735579 0" />
       <axis xyz="1 0 0"/>
       <limit effort="0.0" lower="-3.14159" upper="3.14159" velocity="0.0"/>
    </joint>
    <link name="Link5">
        <inertial>
            <origin xyz="0 0.4862397246458446 0" rpy="0 0 0"/>
            <mass value="1" />
            <inertia ixx="100" ixy="0" ixz="0" iyy="100" iyz="0" izz="100" />
        </inertial>
        <visual>
            <origin xyz="0 0.4862397246458446 0" rpy="0 0 0"/>
            <geometry>
                <box size="1.2203225708195409 0.9724794492916892 0.7393264118363885" />
            </geometry>
            <material name="Blue">
                <color rgba="0.0 0.0 1.0 1.0"/>
            </material>
        </visual>
        <collision>
            <origin xyz="0 0.4862397246458446 0" rpy="0 0 0"/>
            <geometry>
                <box size="1.2203225708195409 0.9724794492916892 0.7393264118363885" />
            </geometry>
        </collision>
    </link>
    <joint name="Link5_Link5XLink0" type="revolute">
       <parent link="Link5"/>
       <child  link="Link5XLink0"/>
       <origin rpy="0 0 0" xyz="0.6101612854097704 0.4862397246458446 0" />
       <axis xyz="1 0 0"/>
       <limit effort="0.0" lower="-3.14159" upper="3.14159" velocity="0.0"/>
    </joint>
    <link name="Link5XLink0">
        <inertial>
            <origin xyz="0.4304426250938011 0 0" rpy="0 0 0"/>
            <mass value="1" />
            <inertia ixx="100" ixy="0" ixz="0" iyy="100" iyz="0" izz="100" />
        </inertial>
        <visual>
            <origin xyz="0.4304426250938011 0 0" rpy="0 0 0"/>
            <geometry>
                <box size="0.8608852501876022 0.5767750769778129 0.7826821473342618" />
            </geometry>
            <material name="Green">
                <color rgba="0.0 1.0 0.0 1.0"/>
            </material>
        </visual>
        <collision>
            <origin xyz="0.4304426250938011 0 0" rpy="0 0 0"/>
            <geometry>
                <box size="0.8608852501876022 0.5767750769778129 0.7826821473342618" />
            </geometry>
        </collision>
    </link>
    <joint name="Link5_Link5MinXLink0" type="revolute">
       <parent link="Link5"/>
       <child  link="Link5MinXLink0"/>
       <origin rpy="0 0 0" xyz="-0.6101612854097704 0.4862397246458446 0" />
       <axis xyz="1 0 0"/>
       <limit effort="0.0" lower="-3.14159" upper="3.14159" velocity="0.0"/>
    </joint>
    <link name="Link5MinXLink0">
        <inertial>
            <origin xyz="-0.3498643336208141 0 0" rpy="0 0 0"/>
            <mass value="1" />
            <inertia ixx="100" ixy="0" ixz="0" iyy="100" iyz="0" izz="100" />
        </inertial>
        <visual>
            <origin xyz="-0.3498643336208141 0 0" rpy="0 0 0"/>
            <geometry>
                <box size="0.6997286672416282 0.6579749541542452 0.9488036044681691" />
            </geometry>
            <material name="Blue">
                <color rgba="0.0 0.0 1.0 1.0"/>
            </material>
        </visual>
        <collision>
            <origin xyz="-0.3498643336208141 0 0" rpy="0 0 0"/>
            <geometry>
                <box size="0.6997286672416282 0.6579749541542452 0.9488036044681691" />
            </geometry>
        </collision>
    </link>
    <joint name="Link5_Link5ZLink0" type="revolute">
       <parent link="Link5"/>
       <child  link="Link5ZLink0"/>
       <origin rpy="0 0 0" xyz="0 -0.4862397246458446 [0.56988056 0.68133767 0.40105773 0.66240372 0.51845138 0.36966321
 0.50366993]" />
       <axis xyz="0 0 1"/>
       <limit effort="0.0" lower="-3.14159" upper="3.14159" velocity="0.0"/>
    </joint>
    <link name="Link5ZLink0">
        <inertial>
            <origin xyz="0 0 0.3675958373110063" rpy="0 0 0"/>
            <mass value="1" />
            <inertia ixx="100" ixy="0" ixz="0" iyy="100" iyz="0" izz="100" />
        </inertial>
        <visual>
            <origin xyz="0 0 0.3675958373110063" rpy="0 0 0"/>
            <geometry>
                <box size="0.7544410242996213 0.914638185002552 0.7351916746220126" />
            </geometry>
            <material name="Green">
                <color rgba="0.0 1.0 0.0 1.0"/>
            </material>
        </visual>
        <collision>
            <origin xyz="0 0 0.3675958373110063" rpy="0 0 0"/>
            <geometry>
                <box size="0.7544410242996213 0.914638185002552 0.7351916746220126" />
            </geometry>
        </collision>
    </link>
</robot>