<robot name = "robot">
    <link name="Link0">
        <inertial>
            <origin xyz="0 0 0.26203515118305093" rpy="0 0 0"/>
            <mass value="1" />
            <inertia ixx="100" ixy="0" ixz="0" iyy="100" iyz="0" izz="100" />
        </inertial>
        <visual>
            <origin xyz="0 0 0.26203515118305093" rpy="0 0 0"/>
            <geometry>
                <box size="0.31235050059415204 0.5844902132802936 0.5240703023661019" />
            </geometry>
            <material name="Blue">
                <color rgba="0.01 0.54 1.0 1.0"/>
            </material>
        </visual>
        <collision>
            <origin xyz="0 0 0.26203515118305093" rpy="0 0 0"/>
            <geometry>
                <box size="0.31235050059415204 0.5844902132802936 0.5240703023661019" />
            </geometry>
        </collision>
    </link>
    <joint name="Link0_Link1" type="revolute">
       <parent link="Link0"/>
       <child  link="Link1"/>
       <origin rpy="0 0 0" xyz="0 0.2922451066401468 0.26203515118305093" />
       <axis xyz="1 0 0"/>
       <limit effort="0.0" lower="-3.14159" upper="3.14159" velocity="0.0"/>
    </joint>
    <link name="Link1">
        <inertial>
            <origin xyz="0 0.21598438869205488 0" rpy="0 0 0"/>
            <mass value="1" />
            <inertia ixx="100" ixy="0" ixz="0" iyy="100" iyz="0" izz="100" />
        </inertial>
        <visual>
            <origin xyz="0 0.21598438869205488 0" rpy="0 0 0"/>
            <geometry>
                <box size="0.2603077426808366 0.43196877738410977 0.3305592508231575" />
            </geometry>
            <material name="Blue">
                <color rgba="0.01 0.54 1.0 1.0"/>
            </material>
        </visual>
        <collision>
            <origin xyz="0 0.21598438869205488 0" rpy="0 0 0"/>
            <geometry>
                <box size="0.2603077426808366 0.43196877738410977 0.3305592508231575" />
            </geometry>
        </collision>
    </link>
    <joint name="Link1_Link1XLink0" type="revolute">
       <parent link="Link1"/>
       <child  link="Link1XLink0"/>
       <origin rpy="0 0 0" xyz="0.1301538713404183 0.21598438869205488 0" />
       <axis xyz="1 0 0"/>
       <limit effort="0.0" lower="-3.14159" upper="3.14159" velocity="0.0"/>
    </joint>
    <link name="Link1XLink0">
        <inertial>
            <origin xyz="0.15264316425207664 0 0" rpy="0 0 0"/>
            <mass value="1" />
            <inertia ixx="100" ixy="0" ixz="0" iyy="100" iyz="0" izz="100" />
        </inertial>
        <visual>
            <origin xyz="0.15264316425207664 0 0" rpy="0 0 0"/>
            <geometry>
                <box size="0.30528632850415327 0.43196877738410977 0.5989442963149919" />
            </geometry>
            <material name="Green">
                <color rgba="0.25 0.76 0.50 1.0"/>
            </material>
        </visual>
        <collision>
            <origin xyz="0.15264316425207664 0 0" rpy="0 0 0"/>
            <geometry>
                <box size="0.30528632850415327 0.43196877738410977 0.5989442963149919" />
            </geometry>
        </collision>
    </link>
    <joint name="Link1_Link1MinXLink0" type="revolute">
       <parent link="Link1"/>
       <child  link="Link1MinXLink0"/>
       <origin rpy="0 0 0" xyz="-0.1301538713404183 0.21598438869205488 0" />
       <axis xyz="1 0 0"/>
       <limit effort="0.0" lower="-3.14159" upper="3.14159" velocity="0.0"/>
    </joint>
    <link name="Link1MinXLink0">
        <inertial>
            <origin xyz="-0.1737136036680038 0 0" rpy="0 0 0"/>
            <mass value="1" />
            <inertia ixx="100" ixy="0" ixz="0" iyy="100" iyz="0" izz="100" />
        </inertial>
        <visual>
            <origin xyz="-0.1737136036680038 0 0" rpy="0 0 0"/>
            <geometry>
                <box size="0.3474272073360076 0.254641410730422 0.36323150948301314" />
            </geometry>
            <material name="Blue">
                <color rgba="0.01 0.54 1.0 1.0"/>
            </material>
        </visual>
        <collision>
            <origin xyz="-0.1737136036680038 0 0" rpy="0 0 0"/>
            <geometry>
                <box size="0.3474272073360076 0.254641410730422 0.36323150948301314" />
            </geometry>
        </collision>
    </link>
    <joint name="Link1_Link1ZLink0" type="revolute">
       <parent link="Link1"/>
       <child  link="Link1ZLink0"/>
       <origin rpy="0 0 0" xyz="0 0.21598438869205488 0.16527962541157876" />
       <axis xyz="0 0 1"/>
       <limit effort="0.0" lower="-3.14159" upper="3.14159" velocity="0.0"/>
    </joint>
    <link name="Link1ZLink0">
        <inertial>
            <origin xyz="0 0 0.2663679705997073" rpy="0 0 0"/>
            <mass value="1" />
            <inertia ixx="100" ixy="0" ixz="0" iyy="100" iyz="0" izz="100" />
        </inertial>
        <visual>
            <origin xyz="0 0 0.2663679705997073" rpy="0 0 0"/>
            <geometry>
                <box size="0.2603077426808366 0.43196877738410977 0.5327359411994146" />
            </geometry>
            <material name="Blue">
                <color rgba="0.01 0.54 1.0 1.0"/>
            </material>
        </visual>
        <collision>
            <origin xyz="0 0 0.2663679705997073" rpy="0 0 0"/>
            <geometry>
                <box size="0.2603077426808366 0.43196877738410977 0.5327359411994146" />
            </geometry>
        </collision>
    </link>
    <joint name="Link1ZLink0_Link1ZLink1" type="revolute">
       <parent link="Link1ZLink0"/>
       <child  link="Link1ZLink1"/>
       <origin rpy="0 0 0" xyz="0 0 0.5327359411994146" />
       <axis xyz="0 0 1"/>
       <limit effort="0.0" lower="-3.14159" upper="3.14159" velocity="0.0"/>
    </joint>
    <link name="Link1ZLink1">
        <inertial>
            <origin xyz="0 0 0.2663679705997073" rpy="0 0 0"/>
            <mass value="1" />
            <inertia ixx="100" ixy="0" ixz="0" iyy="100" iyz="0" izz="100" />
        </inertial>
        <visual>
            <origin xyz="0 0 0.2663679705997073" rpy="0 0 0"/>
            <geometry>
                <box size="0.2603077426808366 0.6225582121809196 0.5327359411994146" />
            </geometry>
            <material name="Green">
                <color rgba="0.25 0.76 0.50 1.0"/>
            </material>
        </visual>
        <collision>
            <origin xyz="0 0 0.2663679705997073" rpy="0 0 0"/>
            <geometry>
                <box size="0.2603077426808366 0.6225582121809196 0.5327359411994146" />
            </geometry>
        </collision>
    </link>
    <joint name="Link1ZLink1_Link1ZLink2" type="revolute">
       <parent link="Link1ZLink1"/>
       <child  link="Link1ZLink2"/>
       <origin rpy="0 0 0" xyz="0 0 0.5327359411994146" />
       <axis xyz="0 0 1"/>
       <limit effort="0.0" lower="-3.14159" upper="3.14159" velocity="0.0"/>
    </joint>
    <link name="Link1ZLink2">
        <inertial>
            <origin xyz="0 0 0.2663679705997073" rpy="0 0 0"/>
            <mass value="1" />
            <inertia ixx="100" ixy="0" ixz="0" iyy="100" iyz="0" izz="100" />
        </inertial>
        <visual>
            <origin xyz="0 0 0.2663679705997073" rpy="0 0 0"/>
            <geometry>
                <box size="0.2603077426808366 0.6225582121809196 0.5327359411994146" />
            </geometry>
            <material name="Blue">
                <color rgba="0.01 0.54 1.0 1.0"/>
            </material>
        </visual>
        <collision>
            <origin xyz="0 0 0.2663679705997073" rpy="0 0 0"/>
            <geometry>
                <box size="0.2603077426808366 0.6225582121809196 0.5327359411994146" />
            </geometry>
        </collision>
    </link>
</robot>