<robot name = "robot">
    <link name="Link0">
        <inertial>
            <origin xyz="0 0 0.3263403420637821" rpy="0 0 0"/>
            <mass value="1" />
            <inertia ixx="100" ixy="0" ixz="0" iyy="100" iyz="0" izz="100" />
        </inertial>
        <visual>
            <origin xyz="0 0 0.3263403420637821" rpy="0 0 0"/>
            <geometry>
                <box size="0.9231531700665616 0.8748260061582775 0.6526806841275642" />
            </geometry>
            <material name="Blue">
                <color rgba="0.01 0.54 1.0 1.0"/>
            </material>
        </visual>
        <collision>
            <origin xyz="0 0 0.3263403420637821" rpy="0 0 0"/>
            <geometry>
                <box size="0.9231531700665616 0.8748260061582775 0.6526806841275642" />
            </geometry>
        </collision>
    </link>
    <joint name="Link0_Link1" type="revolute">
       <parent link="Link0"/>
       <child  link="Link1"/>
       <origin rpy="0 0 0" xyz="0 0.4374130030791388 0.5164823086080519" />
       <axis xyz="1 0 0"/>
       <limit effort="0.0" lower="-3.14159" upper="3.14159" velocity="0.0"/>
    </joint>
    <link name="Link1">
        <inertial>
            <origin xyz="0 0.42097340810222184 0" rpy="0 0 0"/>
            <mass value="1" />
            <inertia ixx="100" ixy="0" ixz="0" iyy="100" iyz="0" izz="100" />
        </inertial>
        <visual>
            <origin xyz="0 0.42097340810222184 0" rpy="0 0 0"/>
            <geometry>
                <box size="0.5908369714005802 0.8419468162044437 0.8227072804239032" />
            </geometry>
            <material name="Green">
                <color rgba="0.25 0.76 0.50 1.0"/>
            </material>
        </visual>
        <collision>
            <origin xyz="0 0.42097340810222184 0" rpy="0 0 0"/>
            <geometry>
                <box size="0.5908369714005802 0.8419468162044437 0.8227072804239032" />
            </geometry>
        </collision>
    </link>
    <joint name="Link1_Link1XLink0" type="revolute">
       <parent link="Link1"/>
       <child  link="Link1XLink0"/>
       <origin rpy="0 0 0" xyz="0.2954184857002901 0.42097340810222184 0" />
       <axis xyz="1 0 0"/>
       <limit effort="0.0" lower="-3.14159" upper="3.14159" velocity="0.0"/>
    </joint>
    <link name="Link1XLink0">
        <inertial>
            <origin xyz="0.4994027697386635 0 0" rpy="0 0 0"/>
            <mass value="1" />
            <inertia ixx="100" ixy="0" ixz="0" iyy="100" iyz="0" izz="100" />
        </inertial>
        <visual>
            <origin xyz="0.4994027697386635 0 0" rpy="0 0 0"/>
            <geometry>
                <box size="0.998805539477327 0.5965383753384272 1.0398291929490644" />
            </geometry>
            <material name="Blue">
                <color rgba="0.01 0.54 1.0 1.0"/>
            </material>
        </visual>
        <collision>
            <origin xyz="0.4994027697386635 0 0" rpy="0 0 0"/>
            <geometry>
                <box size="0.998805539477327 0.5965383753384272 1.0398291929490644" />
            </geometry>
        </collision>
    </link>
    <joint name="Link1_Link1MinXLink0" type="revolute">
       <parent link="Link1"/>
       <child  link="Link1MinXLink0"/>
       <origin rpy="0 0 0" xyz="-0.2954184857002901 0.42097340810222184 0" />
       <axis xyz="1 0 0"/>
       <limit effort="0.0" lower="-3.14159" upper="3.14159" velocity="0.0"/>
    </joint>
    <link name="Link1MinXLink0">
        <inertial>
            <origin xyz="-0.255584857339209 0 0" rpy="0 0 0"/>
            <mass value="1" />
            <inertia ixx="100" ixy="0" ixz="0" iyy="100" iyz="0" izz="100" />
        </inertial>
        <visual>
            <origin xyz="-0.255584857339209 0 0" rpy="0 0 0"/>
            <geometry>
                <box size="0.511169714678418 0.8406323886132745 0.7863920422468031" />
            </geometry>
            <material name="Blue">
                <color rgba="0.01 0.54 1.0 1.0"/>
            </material>
        </visual>
        <collision>
            <origin xyz="-0.255584857339209 0 0" rpy="0 0 0"/>
            <geometry>
                <box size="0.511169714678418 0.8406323886132745 0.7863920422468031" />
            </geometry>
        </collision>
    </link>
    <joint name="Link1_Link2" type="revolute">
       <parent link="Link1"/>
       <child  link="Link2"/>
       <origin rpy="0 0 0" xyz="0 0.8419468162044437 0" />
       <axis xyz="1 0 0"/>
       <limit effort="0.0" lower="-3.14159" upper="3.14159" velocity="0.0"/>
    </joint>
    <link name="Link2">
        <inertial>
            <origin xyz="0 0.549944385568261 0" rpy="0 0 0"/>
            <mass value="1" />
            <inertia ixx="100" ixy="0" ixz="0" iyy="100" iyz="0" izz="100" />
        </inertial>
        <visual>
            <origin xyz="0 0.549944385568261 0" rpy="0 0 0"/>
            <geometry>
                <box size="1.0296311563919622 1.099888771136522 0.7346509702405941" />
            </geometry>
            <material name="Blue">
                <color rgba="0.01 0.54 1.0 1.0"/>
            </material>
        </visual>
        <collision>
            <origin xyz="0 0.549944385568261 0" rpy="0 0 0"/>
            <geometry>
                <box size="1.0296311563919622 1.099888771136522 0.7346509702405941" />
            </geometry>
        </collision>
    </link>
    <joint name="Link2_Link2XLink0" type="revolute">
       <parent link="Link2"/>
       <child  link="Link2XLink0"/>
       <origin rpy="0 0 0" xyz="0.5148155781959811 0.549944385568261 0" />
       <axis xyz="1 0 0"/>
       <limit effort="0.0" lower="-3.14159" upper="3.14159" velocity="0.0"/>
    </joint>
    <link name="Link2XLink0">
        <inertial>
            <origin xyz="0.4212905579800852 0 0" rpy="0 0 0"/>
            <mass value="1" />
            <inertia ixx="100" ixy="0" ixz="0" iyy="100" iyz="0" izz="100" />
        </inertial>
        <visual>
            <origin xyz="0.4212905579800852 0 0" rpy="0 0 0"/>
            <geometry>
                <box size="0.8425811159601704 0.9238563648737677 0.5079163309545593" />
            </geometry>
            <material name="Blue">
                <color rgba="0.01 0.54 1.0 1.0"/>
            </material>
        </visual>
        <collision>
            <origin xyz="0.4212905579800852 0 0" rpy="0 0 0"/>
            <geometry>
                <box size="0.8425811159601704 0.9238563648737677 0.5079163309545593" />
            </geometry>
        </collision>
    </link>
    <joint name="Link2_Link2MinXLink0" type="revolute">
       <parent link="Link2"/>
       <child  link="Link2MinXLink0"/>
       <origin rpy="0 0 0" xyz="-0.5148155781959811 0.549944385568261 0" />
       <axis xyz="1 0 0"/>
       <limit effort="0.0" lower="-3.14159" upper="3.14159" velocity="0.0"/>
    </joint>
    <link name="Link2MinXLink0">
        <inertial>
            <origin xyz="-0.3185538205894951 0 0" rpy="0 0 0"/>
            <mass value="1" />
            <inertia ixx="100" ixy="0" ixz="0" iyy="100" iyz="0" izz="100" />
        </inertial>
        <visual>
            <origin xyz="-0.3185538205894951 0 0" rpy="0 0 0"/>
            <geometry>
                <box size="0.6371076411789902 0.8458985252971558 0.5397283336878741" />
            </geometry>
            <material name="Green">
                <color rgba="0.25 0.76 0.50 1.0"/>
            </material>
        </visual>
        <collision>
            <origin xyz="-0.3185538205894951 0 0" rpy="0 0 0"/>
            <geometry>
                <box size="0.6371076411789902 0.8458985252971558 0.5397283336878741" />
            </geometry>
        </collision>
    </link>
    <joint name="Link2_Link3" type="revolute">
       <parent link="Link2"/>
       <child  link="Link3"/>
       <origin rpy="0 0 0" xyz="0 1.099888771136522 0" />
       <axis xyz="1 0 0"/>
       <limit effort="0.0" lower="-3.14159" upper="3.14159" velocity="0.0"/>
    </joint>
    <link name="Link3">
        <inertial>
            <origin xyz="0 0.33618785027081366 0" rpy="0 0 0"/>
            <mass value="1" />
            <inertia ixx="100" ixy="0" ixz="0" iyy="100" iyz="0" izz="100" />
        </inertial>
        <visual>
            <origin xyz="0 0.33618785027081366 0" rpy="0 0 0"/>
            <geometry>
                <box size="0.5149419940786237 0.6723757005416273 1.0329646172161038" />
            </geometry>
            <material name="Green">
                <color rgba="0.25 0.76 0.50 1.0"/>
            </material>
        </visual>
        <collision>
            <origin xyz="0 0.33618785027081366 0" rpy="0 0 0"/>
            <geometry>
                <box size="0.5149419940786237 0.6723757005416273 1.0329646172161038" />
            </geometry>
        </collision>
    </link>
    <joint name="Link3_Link3XLink0" type="revolute">
       <parent link="Link3"/>
       <child  link="Link3XLink0"/>
       <origin rpy="0 0 0" xyz="0.25747099703931187 0.33618785027081366 0" />
       <axis xyz="1 0 0"/>
       <limit effort="0.0" lower="-3.14159" upper="3.14159" velocity="0.0"/>
    </joint>
    <link name="Link3XLink0">
        <inertial>
            <origin xyz="0.5410055713407539 0 0" rpy="0 0 0"/>
            <mass value="1" />
            <inertia ixx="100" ixy="0" ixz="0" iyy="100" iyz="0" izz="100" />
        </inertial>
        <visual>
            <origin xyz="0.5410055713407539 0 0" rpy="0 0 0"/>
            <geometry>
                <box size="1.0820111426815078 0.6723757005416273 0.5969967981514471" />
            </geometry>
            <material name="Green">
                <color rgba="0.25 0.76 0.50 1.0"/>
            </material>
        </visual>
        <collision>
            <origin xyz="0.5410055713407539 0 0" rpy="0 0 0"/>
            <geometry>
                <box size="1.0820111426815078 0.6723757005416273 0.5969967981514471" />
            </geometry>
        </collision>
    </link>
    <joint name="Link3_Link3MinXLink0" type="revolute">
       <parent link="Link3"/>
       <child  link="Link3MinXLink0"/>
       <origin rpy="0 0 0" xyz="-0.25747099703931187 0.33618785027081366 0" />
       <axis xyz="1 0 0"/>
       <limit effort="0.0" lower="-3.14159" upper="3.14159" velocity="0.0"/>
    </joint>
    <link name="Link3MinXLink0">
        <inertial>
            <origin xyz="-0.34447929310812403 0 0" rpy="0 0 0"/>
            <mass value="1" />
            <inertia ixx="100" ixy="0" ixz="0" iyy="100" iyz="0" izz="100" />
        </inertial>
        <visual>
            <origin xyz="-0.34447929310812403 0 0" rpy="0 0 0"/>
            <geometry>
                <box size="0.6889585862162481 0.6723757005416273 0.7599220013902244" />
            </geometry>
            <material name="Blue">
                <color rgba="0.01 0.54 1.0 1.0"/>
            </material>
        </visual>
        <collision>
            <origin xyz="-0.34447929310812403 0 0" rpy="0 0 0"/>
            <geometry>
                <box size="0.6889585862162481 0.6723757005416273 0.7599220013902244" />
            </geometry>
        </collision>
    </link>
</robot>