<robot name = "robot">
    <link name="Link0">
        <inertial>
            <origin xyz="0 0 0.13951908951152497" rpy="0 0 0"/>
            <mass value="1" />
            <inertia ixx="100" ixy="0" ixz="0" iyy="100" iyz="0" izz="100" />
        </inertial>
        <visual>
            <origin xyz="0 0 0.13951908951152497" rpy="0 0 0"/>
            <geometry>
                <box size="0.4014870626261806 0.4565350553800465 0.27903817902304995" />
            </geometry>
            <material name="Blue">
                <color rgba="0.01 0.54 1.0 1.0"/>
            </material>
        </visual>
        <collision>
            <origin xyz="0 0 0.13951908951152497" rpy="0 0 0"/>
            <geometry>
                <box size="0.4014870626261806 0.4565350553800465 0.27903817902304995" />
            </geometry>
        </collision>
    </link>
    <joint name="Link0_Link1" type="revolute">
       <parent link="Link0"/>
       <child  link="Link1"/>
       <origin rpy="0 0 0" xyz="0 0.22826752769002326 0.19412610867519042" />
       <axis xyz="1 0 0"/>
       <limit effort="0.0" lower="-3.14159" upper="3.14159" velocity="0.0"/>
    </joint>
    <link name="Link1">
        <inertial>
            <origin xyz="0 0.2213973159778041 0" rpy="0 0 0"/>
            <mass value="1" />
            <inertia ixx="100" ixy="0" ixz="0" iyy="100" iyz="0" izz="100" />
        </inertial>
        <visual>
            <origin xyz="0 0.2213973159778041 0" rpy="0 0 0"/>
            <geometry>
                <box size="0.4317410388848055 0.4427946319556082 0.1795643497925664" />
            </geometry>
            <material name="Blue">
                <color rgba="0.01 0.54 1.0 1.0"/>
            </material>
        </visual>
        <collision>
            <origin xyz="0 0.2213973159778041 0" rpy="0 0 0"/>
            <geometry>
                <box size="0.4317410388848055 0.4427946319556082 0.1795643497925664" />
            </geometry>
        </collision>
    </link>
    <joint name="Link1_Link1XLink0" type="revolute">
       <parent link="Link1"/>
       <child  link="Link1XLink0"/>
       <origin rpy="0 0 0" xyz="0.21587051944240274 0.2213973159778041 0" />
       <axis xyz="1 0 0"/>
       <limit effort="0.0" lower="-3.14159" upper="3.14159" velocity="0.0"/>
    </joint>
    <link name="Link1XLink0">
        <inertial>
            <origin xyz="0.26504786920312856 0 0" rpy="0 0 0"/>
            <mass value="1" />
            <inertia ixx="100" ixy="0" ixz="0" iyy="100" iyz="0" izz="100" />
        </inertial>
        <visual>
            <origin xyz="0.26504786920312856 0 0" rpy="0 0 0"/>
            <geometry>
                <box size="0.5300957384062571 0.4144786691435487 0.3811158007807833" />
            </geometry>
            <material name="Green">
                <color rgba="0.25 0.76 0.50 1.0"/>
            </material>
        </visual>
        <collision>
            <origin xyz="0.26504786920312856 0 0" rpy="0 0 0"/>
            <geometry>
                <box size="0.5300957384062571 0.4144786691435487 0.3811158007807833" />
            </geometry>
        </collision>
    </link>
    <joint name="Link1_Link1MinXLink0" type="revolute">
       <parent link="Link1"/>
       <child  link="Link1MinXLink0"/>
       <origin rpy="0 0 0" xyz="-0.21587051944240274 0.2213973159778041 0" />
       <axis xyz="1 0 0"/>
       <limit effort="0.0" lower="-3.14159" upper="3.14159" velocity="0.0"/>
    </joint>
    <link name="Link1MinXLink0">
        <inertial>
            <origin xyz="-0.2333163153864411 0 0" rpy="0 0 0"/>
            <mass value="1" />
            <inertia ixx="100" ixy="0" ixz="0" iyy="100" iyz="0" izz="100" />
        </inertial>
        <visual>
            <origin xyz="-0.2333163153864411 0 0" rpy="0 0 0"/>
            <geometry>
                <box size="0.4666326307728822 0.3513078339695195 0.2548767070963295" />
            </geometry>
            <material name="Green">
                <color rgba="0.25 0.76 0.50 1.0"/>
            </material>
        </visual>
        <collision>
            <origin xyz="-0.2333163153864411 0 0" rpy="0 0 0"/>
            <geometry>
                <box size="0.4666326307728822 0.3513078339695195 0.2548767070963295" />
            </geometry>
        </collision>
    </link>
    <joint name="Link1_Link1ZLink0" type="revolute">
       <parent link="Link1"/>
       <child  link="Link1ZLink0"/>
       <origin rpy="0 0 0" xyz="0 0.2213973159778041 0.0897821748962832" />
       <axis xyz="0 0 1"/>
       <limit effort="0.0" lower="-3.14159" upper="3.14159" velocity="0.0"/>
    </joint>
    <link name="Link1ZLink0">
        <inertial>
            <origin xyz="0 0 0.07966410495120985" rpy="0 0 0"/>
            <mass value="1" />
            <inertia ixx="100" ixy="0" ixz="0" iyy="100" iyz="0" izz="100" />
        </inertial>
        <visual>
            <origin xyz="0 0 0.07966410495120985" rpy="0 0 0"/>
            <geometry>
                <box size="0.3044754003309187 0.2231153383713474 0.1593282099024197" />
            </geometry>
            <material name="Green">
                <color rgba="0.25 0.76 0.50 1.0"/>
            </material>
        </visual>
        <collision>
            <origin xyz="0 0 0.07966410495120985" rpy="0 0 0"/>
            <geometry>
                <box size="0.3044754003309187 0.2231153383713474 0.1593282099024197" />
            </geometry>
        </collision>
    </link>
    <joint name="Link1ZLink0_Link1ZLink1" type="revolute">
       <parent link="Link1ZLink0"/>
       <child  link="Link1ZLink1"/>
       <origin rpy="0 0 0" xyz="0 0 0.1593282099024197" />
       <axis xyz="0 0 1"/>
       <limit effort="0.0" lower="-3.14159" upper="3.14159" velocity="0.0"/>
    </joint>
    <link name="Link1ZLink1">
        <inertial>
            <origin xyz="0 0 0.07966410495120985" rpy="0 0 0"/>
            <mass value="1" />
            <inertia ixx="100" ixy="0" ixz="0" iyy="100" iyz="0" izz="100" />
        </inertial>
        <visual>
            <origin xyz="0 0 0.07966410495120985" rpy="0 0 0"/>
            <geometry>
                <box size="0.3044754003309187 0.2231153383713474 0.1593282099024197" />
            </geometry>
            <material name="Green">
                <color rgba="0.25 0.76 0.50 1.0"/>
            </material>
        </visual>
        <collision>
            <origin xyz="0 0 0.07966410495120985" rpy="0 0 0"/>
            <geometry>
                <box size="0.3044754003309187 0.2231153383713474 0.1593282099024197" />
            </geometry>
        </collision>
    </link>
</robot>