<robot name = "robot">
    <link name="Link0">
        <inertial>
            <origin xyz="0 0 0.4829299216741687" rpy="0 0 0"/>
            <mass value="1" />
            <inertia ixx="100" ixy="0" ixz="0" iyy="100" iyz="0" izz="100" />
        </inertial>
        <visual>
            <origin xyz="0 0 0.4829299216741687" rpy="0 0 0"/>
            <geometry>
                <box size="1.0191722496877418 0.6849589381784777 0.9658598433483374" />
            </geometry>
            <material name="Blue">
                <color rgba="0.01 0.54 1.0 1.0"/>
            </material>
        </visual>
        <collision>
            <origin xyz="0 0 0.4829299216741687" rpy="0 0 0"/>
            <geometry>
                <box size="1.0191722496877418 0.6849589381784777 0.9658598433483374" />
            </geometry>
        </collision>
    </link>
    <joint name="Link0_Link1" type="revolute">
       <parent link="Link0"/>
       <child  link="Link1"/>
       <origin rpy="0 0 0" xyz="0 0.3424794690892389 0.4829299216741687" />
       <axis xyz="1 0 0"/>
       <limit effort="0.0" lower="-3.14159" upper="3.14159" velocity="0.0"/>
    </joint>
    <link name="Link1">
        <inertial>
            <origin xyz="0 0.3641747816494174 0" rpy="0 0 0"/>
            <mass value="1" />
            <inertia ixx="100" ixy="0" ixz="0" iyy="100" iyz="0" izz="100" />
        </inertial>
        <visual>
            <origin xyz="0 0.3641747816494174 0" rpy="0 0 0"/>
            <geometry>
                <box size="0.8457931247552823 0.7283495632988348 0.5787660895729354" />
            </geometry>
            <material name="Green">
                <color rgba="0.25 0.76 0.50 1.0"/>
            </material>
        </visual>
        <collision>
            <origin xyz="0 0.3641747816494174 0" rpy="0 0 0"/>
            <geometry>
                <box size="0.8457931247552823 0.7283495632988348 0.5787660895729354" />
            </geometry>
        </collision>
    </link>
    <joint name="Link1_Link1XLink0" type="revolute">
       <parent link="Link1"/>
       <child  link="Link1XLink0"/>
       <origin rpy="0 0 0" xyz="0.42289656237764117 0.3641747816494174 0" />
       <axis xyz="1 0 0"/>
       <limit effort="0.0" lower="-3.14159" upper="3.14159" velocity="0.0"/>
    </joint>
    <link name="Link1XLink0">
        <inertial>
            <origin xyz="0.3194139128091357 0 0" rpy="0 0 0"/>
            <mass value="1" />
            <inertia ixx="100" ixy="0" ixz="0" iyy="100" iyz="0" izz="100" />
        </inertial>
        <visual>
            <origin xyz="0.3194139128091357 0 0" rpy="0 0 0"/>
            <geometry>
                <box size="0.6388278256182714 0.7283495632988348 1.0607016741729582" />
            </geometry>
            <material name="Green">
                <color rgba="0.25 0.76 0.50 1.0"/>
            </material>
        </visual>
        <collision>
            <origin xyz="0.3194139128091357 0 0" rpy="0 0 0"/>
            <geometry>
                <box size="0.6388278256182714 0.7283495632988348 1.0607016741729582" />
            </geometry>
        </collision>
    </link>
    <joint name="Link1_Link1MinXLink0" type="revolute">
       <parent link="Link1"/>
       <child  link="Link1MinXLink0"/>
       <origin rpy="0 0 0" xyz="-0.42289656237764117 0.3641747816494174 0" />
       <axis xyz="1 0 0"/>
       <limit effort="0.0" lower="-3.14159" upper="3.14159" velocity="0.0"/>
    </joint>
    <link name="Link1MinXLink0">
        <inertial>
            <origin xyz="-0.5239076425014175 0 0" rpy="0 0 0"/>
            <mass value="1" />
            <inertia ixx="100" ixy="0" ixz="0" iyy="100" iyz="0" izz="100" />
        </inertial>
        <visual>
            <origin xyz="-0.5239076425014175 0 0" rpy="0 0 0"/>
            <geometry>
                <box size="1.047815285002835 0.7283495632988348 0.9926752319339349" />
            </geometry>
            <material name="Green">
                <color rgba="0.25 0.76 0.50 1.0"/>
            </material>
        </visual>
        <collision>
            <origin xyz="-0.5239076425014175 0 0" rpy="0 0 0"/>
            <geometry>
                <box size="1.047815285002835 0.7283495632988348 0.9926752319339349" />
            </geometry>
        </collision>
    </link>
    <joint name="Link1_Link1ZLink0" type="revolute">
       <parent link="Link1"/>
       <child  link="Link1ZLink0"/>
       <origin rpy="0 0 0" xyz="0 0.3641747816494174 0.2893830447864677" />
       <axis xyz="0 0 1"/>
       <limit effort="0.0" lower="-3.14159" upper="3.14159" velocity="0.0"/>
    </joint>
    <link name="Link1ZLink0">
        <inertial>
            <origin xyz="0 0 0.2854288137142691" rpy="0 0 0"/>
            <mass value="1" />
            <inertia ixx="100" ixy="0" ixz="0" iyy="100" iyz="0" izz="100" />
        </inertial>
        <visual>
            <origin xyz="0 0 0.2854288137142691" rpy="0 0 0"/>
            <geometry>
                <box size="0.8457931247552823 0.5378456394793591 0.5708576274285382" />
            </geometry>
            <material name="Green">
                <color rgba="0.25 0.76 0.50 1.0"/>
            </material>
        </visual>
        <collision>
            <origin xyz="0 0 0.2854288137142691" rpy="0 0 0"/>
            <geometry>
                <box size="0.8457931247552823 0.5378456394793591 0.5708576274285382" />
            </geometry>
        </collision>
    </link>
    <joint name="Link1_Link2" type="revolute">
       <parent link="Link1"/>
       <child  link="Link2"/>
       <origin rpy="0 0 0" xyz="0 0.7283495632988348 0" />
       <axis xyz="1 0 0"/>
       <limit effort="0.0" lower="-3.14159" upper="3.14159" velocity="0.0"/>
    </joint>
    <link name="Link2">
        <inertial>
            <origin xyz="0 0.4060002278882586 0" rpy="0 0 0"/>
            <mass value="1" />
            <inertia ixx="100" ixy="0" ixz="0" iyy="100" iyz="0" izz="100" />
        </inertial>
        <visual>
            <origin xyz="0 0.4060002278882586 0" rpy="0 0 0"/>
            <geometry>
                <box size="0.8428823825700613 0.8120004557765172 0.8651217925107135" />
            </geometry>
            <material name="Blue">
                <color rgba="0.01 0.54 1.0 1.0"/>
            </material>
        </visual>
        <collision>
            <origin xyz="0 0.4060002278882586 0" rpy="0 0 0"/>
            <geometry>
                <box size="0.8428823825700613 0.8120004557765172 0.8651217925107135" />
            </geometry>
        </collision>
    </link>
    <joint name="Link2_Link2XLink0" type="revolute">
       <parent link="Link2"/>
       <child  link="Link2XLink0"/>
       <origin rpy="0 0 0" xyz="0.42144119128503066 0.4060002278882586 0" />
       <axis xyz="1 0 0"/>
       <limit effort="0.0" lower="-3.14159" upper="3.14159" velocity="0.0"/>
    </joint>
    <link name="Link2XLink0">
        <inertial>
            <origin xyz="0.5477549146203706 0 0" rpy="0 0 0"/>
            <mass value="1" />
            <inertia ixx="100" ixy="0" ixz="0" iyy="100" iyz="0" izz="100" />
        </inertial>
        <visual>
            <origin xyz="0.5477549146203706 0 0" rpy="0 0 0"/>
            <geometry>
                <box size="1.0955098292407413 0.8028452010096268 0.7944039062212105" />
            </geometry>
            <material name="Green">
                <color rgba="0.25 0.76 0.50 1.0"/>
            </material>
        </visual>
        <collision>
            <origin xyz="0.5477549146203706 0 0" rpy="0 0 0"/>
            <geometry>
                <box size="1.0955098292407413 0.8028452010096268 0.7944039062212105" />
            </geometry>
        </collision>
    </link>
    <joint name="Link2_Link2MinXLink0" type="revolute">
       <parent link="Link2"/>
       <child  link="Link2MinXLink0"/>
       <origin rpy="0 0 0" xyz="-0.42144119128503066 0.4060002278882586 0" />
       <axis xyz="1 0 0"/>
       <limit effort="0.0" lower="-3.14159" upper="3.14159" velocity="0.0"/>
    </joint>
    <link name="Link2MinXLink0">
        <inertial>
            <origin xyz="-0.5220144072271355 0 0" rpy="0 0 0"/>
            <mass value="1" />
            <inertia ixx="100" ixy="0" ixz="0" iyy="100" iyz="0" izz="100" />
        </inertial>
        <visual>
            <origin xyz="-0.5220144072271355 0 0" rpy="0 0 0"/>
            <geometry>
                <box size="1.044028814454271 0.7992659585201314 0.6441780224584256" />
            </geometry>
            <material name="Green">
                <color rgba="0.25 0.76 0.50 1.0"/>
            </material>
        </visual>
        <collision>
            <origin xyz="-0.5220144072271355 0 0" rpy="0 0 0"/>
            <geometry>
                <box size="1.044028814454271 0.7992659585201314 0.6441780224584256" />
            </geometry>
        </collision>
    </link>
    <joint name="Link2_Link2ZLink0" type="revolute">
       <parent link="Link2"/>
       <child  link="Link2ZLink0"/>
       <origin rpy="0 0 0" xyz="0 0.4060002278882586 0.43256089625535676" />
       <axis xyz="0 0 1"/>
       <limit effort="0.0" lower="-3.14159" upper="3.14159" velocity="0.0"/>
    </joint>
    <link name="Link2ZLink0">
        <inertial>
            <origin xyz="0 0 0.31784236293281914" rpy="0 0 0"/>
            <mass value="1" />
            <inertia ixx="100" ixy="0" ixz="0" iyy="100" iyz="0" izz="100" />
        </inertial>
        <visual>
            <origin xyz="0 0 0.31784236293281914" rpy="0 0 0"/>
            <geometry>
                <box size="0.6450679112740836 0.8120004557765172 0.6356847258656383" />
            </geometry>
            <material name="Green">
                <color rgba="0.25 0.76 0.50 1.0"/>
            </material>
        </visual>
        <collision>
            <origin xyz="0 0 0.31784236293281914" rpy="0 0 0"/>
            <geometry>
                <box size="0.6450679112740836 0.8120004557765172 0.6356847258656383" />
            </geometry>
        </collision>
    </link>
    <joint name="Link2_Link3" type="revolute">
       <parent link="Link2"/>
       <child  link="Link3"/>
       <origin rpy="0 0 0" xyz="0 0.8120004557765172 0" />
       <axis xyz="1 0 0"/>
       <limit effort="0.0" lower="-3.14159" upper="3.14159" velocity="0.0"/>
    </joint>
    <link name="Link3">
        <inertial>
            <origin xyz="0 0.3082496398075366 0" rpy="0 0 0"/>
            <mass value="1" />
            <inertia ixx="100" ixy="0" ixz="0" iyy="100" iyz="0" izz="100" />
        </inertial>
        <visual>
            <origin xyz="0 0.3082496398075366 0" rpy="0 0 0"/>
            <geometry>
                <box size="1.0721877568010236 0.6164992796150732 0.9342152260276515" />
            </geometry>
            <material name="Green">
                <color rgba="0.25 0.76 0.50 1.0"/>
            </material>
        </visual>
        <collision>
            <origin xyz="0 0.3082496398075366 0" rpy="0 0 0"/>
            <geometry>
                <box size="1.0721877568010236 0.6164992796150732 0.9342152260276515" />
            </geometry>
        </collision>
    </link>
    <joint name="Link3_Link3XLink0" type="revolute">
       <parent link="Link3"/>
       <child  link="Link3XLink0"/>
       <origin rpy="0 0 0" xyz="0.5360938784005118 0.3082496398075366 0" />
       <axis xyz="1 0 0"/>
       <limit effort="0.0" lower="-3.14159" upper="3.14159" velocity="0.0"/>
    </joint>
    <link name="Link3XLink0">
        <inertial>
            <origin xyz="0.3654470468851897 0 0" rpy="0 0 0"/>
            <mass value="1" />
            <inertia ixx="100" ixy="0" ixz="0" iyy="100" iyz="0" izz="100" />
        </inertial>
        <visual>
            <origin xyz="0.3654470468851897 0 0" rpy="0 0 0"/>
            <geometry>
                <box size="0.7308940937703794 0.6164992796150732 0.8878907436534687" />
            </geometry>
            <material name="Blue">
                <color rgba="0.01 0.54 1.0 1.0"/>
            </material>
        </visual>
        <collision>
            <origin xyz="0.3654470468851897 0 0" rpy="0 0 0"/>
            <geometry>
                <box size="0.7308940937703794 0.6164992796150732 0.8878907436534687" />
            </geometry>
        </collision>
    </link>
    <joint name="Link3_Link3MinXLink0" type="revolute">
       <parent link="Link3"/>
       <child  link="Link3MinXLink0"/>
       <origin rpy="0 0 0" xyz="-0.5360938784005118 0.3082496398075366 0" />
       <axis xyz="1 0 0"/>
       <limit effort="0.0" lower="-3.14159" upper="3.14159" velocity="0.0"/>
    </joint>
    <link name="Link3MinXLink0">
        <inertial>
            <origin xyz="-0.41900852161944896 0 0" rpy="0 0 0"/>
            <mass value="1" />
            <inertia ixx="100" ixy="0" ixz="0" iyy="100" iyz="0" izz="100" />
        </inertial>
        <visual>
            <origin xyz="-0.41900852161944896 0 0" rpy="0 0 0"/>
            <geometry>
                <box size="0.8380170432388979 0.6164992796150732 0.8501667126661963" />
            </geometry>
            <material name="Blue">
                <color rgba="0.01 0.54 1.0 1.0"/>
            </material>
        </visual>
        <collision>
            <origin xyz="-0.41900852161944896 0 0" rpy="0 0 0"/>
            <geometry>
                <box size="0.8380170432388979 0.6164992796150732 0.8501667126661963" />
            </geometry>
        </collision>
    </link>
    <joint name="Link3_Link3ZLink0" type="revolute">
       <parent link="Link3"/>
       <child  link="Link3ZLink0"/>
       <origin rpy="0 0 0" xyz="0 0.3082496398075366 0.46710761301382575" />
       <axis xyz="0 0 1"/>
       <limit effort="0.0" lower="-3.14159" upper="3.14159" velocity="0.0"/>
    </joint>
    <link name="Link3ZLink0">
        <inertial>
            <origin xyz="0 0 0.4058847617792798" rpy="0 0 0"/>
            <mass value="1" />
            <inertia ixx="100" ixy="0" ixz="0" iyy="100" iyz="0" izz="100" />
        </inertial>
        <visual>
            <origin xyz="0 0 0.4058847617792798" rpy="0 0 0"/>
            <geometry>
                <box size="0.6607189034133389 0.6164992796150732 0.8117695235585596" />
            </geometry>
            <material name="Green">
                <color rgba="0.25 0.76 0.50 1.0"/>
            </material>
        </visual>
        <collision>
            <origin xyz="0 0 0.4058847617792798" rpy="0 0 0"/>
            <geometry>
                <box size="0.6607189034133389 0.6164992796150732 0.8117695235585596" />
            </geometry>
        </collision>
    </link>
</robot>