<robot name = "robot">
    <link name="Link0">
        <inertial>
            <origin xyz="0 0 0.3606708764507723" rpy="0 0 0"/>
            <mass value="1" />
            <inertia ixx="100" ixy="0" ixz="0" iyy="100" iyz="0" izz="100" />
        </inertial>
        <visual>
            <origin xyz="0 0 0.3606708764507723" rpy="0 0 0"/>
            <geometry>
                <box size="0.9540880883871701 0.6955637188224455 0.7213417529015446" />
            </geometry>
            <material name="Blue">
                <color rgba="0.01 0.54 1.0 1.0"/>
            </material>
        </visual>
        <collision>
            <origin xyz="0 0 0.3606708764507723" rpy="0 0 0"/>
            <geometry>
                <box size="0.9540880883871701 0.6955637188224455 0.7213417529015446" />
            </geometry>
        </collision>
    </link>
    <joint name="Link0_Link1" type="revolute">
       <parent link="Link0"/>
       <child  link="Link1"/>
       <origin rpy="0 0 0" xyz="0 0.34778185941122275 0.3606708764507723" />
       <axis xyz="1 0 0"/>
       <limit effort="0.0" lower="-3.14159" upper="3.14159" velocity="0.0"/>
    </joint>
    <link name="Link1">
        <inertial>
            <origin xyz="0 0.2877519958931875 0" rpy="0 0 0"/>
            <mass value="1" />
            <inertia ixx="100" ixy="0" ixz="0" iyy="100" iyz="0" izz="100" />
        </inertial>
        <visual>
            <origin xyz="0 0.2877519958931875 0" rpy="0 0 0"/>
            <geometry>
                <box size="0.7670703072782246 0.575503991786375 0.5950399294580361" />
            </geometry>
            <material name="Blue">
                <color rgba="0.01 0.54 1.0 1.0"/>
            </material>
        </visual>
        <collision>
            <origin xyz="0 0.2877519958931875 0" rpy="0 0 0"/>
            <geometry>
                <box size="0.7670703072782246 0.575503991786375 0.5950399294580361" />
            </geometry>
        </collision>
    </link>
    <joint name="Link1_Link1XLink0" type="revolute">
       <parent link="Link1"/>
       <child  link="Link1XLink0"/>
       <origin rpy="0 0 0" xyz="0.3835351536391123 0.2877519958931875 0" />
       <axis xyz="1 0 0"/>
       <limit effort="0.0" lower="-3.14159" upper="3.14159" velocity="0.0"/>
    </joint>
    <link name="Link1XLink0">
        <inertial>
            <origin xyz="0.3000212331644801 0 0" rpy="0 0 0"/>
            <mass value="1" />
            <inertia ixx="100" ixy="0" ixz="0" iyy="100" iyz="0" izz="100" />
        </inertial>
        <visual>
            <origin xyz="0.3000212331644801 0 0" rpy="0 0 0"/>
            <geometry>
                <box size="0.6000424663289602 0.575503991786375 0.9826604230540651" />
            </geometry>
            <material name="Green">
                <color rgba="0.25 0.76 0.50 1.0"/>
            </material>
        </visual>
        <collision>
            <origin xyz="0.3000212331644801 0 0" rpy="0 0 0"/>
            <geometry>
                <box size="0.6000424663289602 0.575503991786375 0.9826604230540651" />
            </geometry>
        </collision>
    </link>
    <joint name="Link1XLink0_Link1XLink1" type="revolute">
       <parent link="Link1XLink0"/>
       <child  link="Link1XLink1"/>
       <origin rpy="0 0 0" xyz="0.6000424663289602 0 0" />
       <axis xyz="1 0 0"/>
       <limit effort="0.0" lower="-3.14159" upper="3.14159" velocity="0.0"/>
    </joint>
    <link name="Link1XLink1">
        <inertial>
            <origin xyz="0.3000212331644801 0 0" rpy="0 0 0"/>
            <mass value="1" />
            <inertia ixx="100" ixy="0" ixz="0" iyy="100" iyz="0" izz="100" />
        </inertial>
        <visual>
            <origin xyz="0.3000212331644801 0 0" rpy="0 0 0"/>
            <geometry>
                <box size="0.6000424663289602 0.6063468060409657 0.9826604230540651" />
            </geometry>
            <material name="Green">
                <color rgba="0.25 0.76 0.50 1.0"/>
            </material>
        </visual>
        <collision>
            <origin xyz="0.3000212331644801 0 0" rpy="0 0 0"/>
            <geometry>
                <box size="0.6000424663289602 0.6063468060409657 0.9826604230540651" />
            </geometry>
        </collision>
    </link>
    <joint name="Link1_Link1MinXLink0" type="revolute">
       <parent link="Link1"/>
       <child  link="Link1MinXLink0"/>
       <origin rpy="0 0 0" xyz="-0.3835351536391123 0.2877519958931875 0" />
       <axis xyz="1 0 0"/>
       <limit effort="0.0" lower="-3.14159" upper="3.14159" velocity="0.0"/>
    </joint>
    <link name="Link1MinXLink0">
        <inertial>
            <origin xyz="-0.28629537569296915 0 0" rpy="0 0 0"/>
            <mass value="1" />
            <inertia ixx="100" ixy="0" ixz="0" iyy="100" iyz="0" izz="100" />
        </inertial>
        <visual>
            <origin xyz="-0.28629537569296915 0 0" rpy="0 0 0"/>
            <geometry>
                <box size="0.5725907513859383 0.575503991786375 0.5538393388763634" />
            </geometry>
            <material name="Blue">
                <color rgba="0.01 0.54 1.0 1.0"/>
            </material>
        </visual>
        <collision>
            <origin xyz="-0.28629537569296915 0 0" rpy="0 0 0"/>
            <geometry>
                <box size="0.5725907513859383 0.575503991786375 0.5538393388763634" />
            </geometry>
        </collision>
    </link>
    <joint name="Link1MinXLink0_Link1MinXLink1" type="revolute">
       <parent link="Link1MinXLink0"/>
       <child  link="Link1MinXLink1"/>
       <origin rpy="0 0 0" xyz="-0.5725907513859383 0 0" />
       <axis xyz="1 0 0"/>
       <limit effort="0.0" lower="-3.14159" upper="3.14159" velocity="0.0"/>
    </joint>
    <link name="Link1MinXLink1">
        <inertial>
            <origin xyz="-0.28629537569296915 0 0" rpy="0 0 0"/>
            <mass value="1" />
            <inertia ixx="100" ixy="0" ixz="0" iyy="100" iyz="0" izz="100" />
        </inertial>
        <visual>
            <origin xyz="-0.28629537569296915 0 0" rpy="0 0 0"/>
            <geometry>
                <box size="0.5725907513859383 0.815687720091461 0.5538393388763634" />
            </geometry>
            <material name="Blue">
                <color rgba="0.01 0.54 1.0 1.0"/>
            </material>
        </visual>
        <collision>
            <origin xyz="-0.28629537569296915 0 0" rpy="0 0 0"/>
            <geometry>
                <box size="0.5725907513859383 0.815687720091461 0.5538393388763634" />
            </geometry>
        </collision>
    </link>
    <joint name="Link1_Link1ZLink0" type="revolute">
       <parent link="Link1"/>
       <child  link="Link1ZLink0"/>
       <origin rpy="0 0 0" xyz="0 0.2877519958931875 0.29751996472901804" />
       <axis xyz="0 0 1"/>
       <limit effort="0.0" lower="-3.14159" upper="3.14159" velocity="0.0"/>
    </joint>
    <link name="Link1ZLink0">
        <inertial>
            <origin xyz="0 0 0.2684934684554723" rpy="0 0 0"/>
            <mass value="1" />
            <inertia ixx="100" ixy="0" ixz="0" iyy="100" iyz="0" izz="100" />
        </inertial>
        <visual>
            <origin xyz="0 0 0.2684934684554723" rpy="0 0 0"/>
            <geometry>
                <box size="0.5817584707969127 0.575503991786375 0.5369869369109446" />
            </geometry>
            <material name="Green">
                <color rgba="0.25 0.76 0.50 1.0"/>
            </material>
        </visual>
        <collision>
            <origin xyz="0 0 0.2684934684554723" rpy="0 0 0"/>
            <geometry>
                <box size="0.5817584707969127 0.575503991786375 0.5369869369109446" />
            </geometry>
        </collision>
    </link>
    <joint name="Link1_Link2" type="revolute">
       <parent link="Link1"/>
       <child  link="Link2"/>
       <origin rpy="0 0 0" xyz="0 0.575503991786375 0" />
       <axis xyz="1 0 0"/>
       <limit effort="0.0" lower="-3.14159" upper="3.14159" velocity="0.0"/>
    </joint>
    <link name="Link2">
        <inertial>
            <origin xyz="0 0.5025247989540937 0" rpy="0 0 0"/>
            <mass value="1" />
            <inertia ixx="100" ixy="0" ixz="0" iyy="100" iyz="0" izz="100" />
        </inertial>
        <visual>
            <origin xyz="0 0.5025247989540937 0" rpy="0 0 0"/>
            <geometry>
                <box size="0.6594740369894366 1.0050495979081875 0.5079622018535078" />
            </geometry>
            <material name="Green">
                <color rgba="0.25 0.76 0.50 1.0"/>
            </material>
        </visual>
        <collision>
            <origin xyz="0 0.5025247989540937 0" rpy="0 0 0"/>
            <geometry>
                <box size="0.6594740369894366 1.0050495979081875 0.5079622018535078" />
            </geometry>
        </collision>
    </link>
    <joint name="Link2_Link2XLink0" type="revolute">
       <parent link="Link2"/>
       <child  link="Link2XLink0"/>
       <origin rpy="0 0 0" xyz="0.3297370184947183 0.5025247989540937 0" />
       <axis xyz="1 0 0"/>
       <limit effort="0.0" lower="-3.14159" upper="3.14159" velocity="0.0"/>
    </joint>
    <link name="Link2XLink0">
        <inertial>
            <origin xyz="0.41755048295083297 0 0" rpy="0 0 0"/>
            <mass value="1" />
            <inertia ixx="100" ixy="0" ixz="0" iyy="100" iyz="0" izz="100" />
        </inertial>
        <visual>
            <origin xyz="0.41755048295083297 0 0" rpy="0 0 0"/>
            <geometry>
                <box size="0.8351009659016659 0.6995652425436393 0.8311015033316682" />
            </geometry>
            <material name="Blue">
                <color rgba="0.01 0.54 1.0 1.0"/>
            </material>
        </visual>
        <collision>
            <origin xyz="0.41755048295083297 0 0" rpy="0 0 0"/>
            <geometry>
                <box size="0.8351009659016659 0.6995652425436393 0.8311015033316682" />
            </geometry>
        </collision>
    </link>
    <joint name="Link2XLink0_Link2XLink1" type="revolute">
       <parent link="Link2XLink0"/>
       <child  link="Link2XLink1"/>
       <origin rpy="0 0 0" xyz="0.8351009659016659 0 0" />
       <axis xyz="1 0 0"/>
       <limit effort="0.0" lower="-3.14159" upper="3.14159" velocity="0.0"/>
    </joint>
    <link name="Link2XLink1">
        <inertial>
            <origin xyz="0.41755048295083297 0 0" rpy="0 0 0"/>
            <mass value="1" />
            <inertia ixx="100" ixy="0" ixz="0" iyy="100" iyz="0" izz="100" />
        </inertial>
        <visual>
            <origin xyz="0.41755048295083297 0 0" rpy="0 0 0"/>
            <geometry>
                <box size="0.8351009659016659 0.6995652425436393 0.8311015033316682" />
            </geometry>
            <material name="Blue">
                <color rgba="0.01 0.54 1.0 1.0"/>
            </material>
        </visual>
        <collision>
            <origin xyz="0.41755048295083297 0 0" rpy="0 0 0"/>
            <geometry>
                <box size="0.8351009659016659 0.6995652425436393 0.8311015033316682" />
            </geometry>
        </collision>
    </link>
    <joint name="Link2_Link2MinXLink0" type="revolute">
       <parent link="Link2"/>
       <child  link="Link2MinXLink0"/>
       <origin rpy="0 0 0" xyz="-0.3297370184947183 0.5025247989540937 0" />
       <axis xyz="1 0 0"/>
       <limit effort="0.0" lower="-3.14159" upper="3.14159" velocity="0.0"/>
    </joint>
    <link name="Link2MinXLink0">
        <inertial>
            <origin xyz="-0.31420841813043576 0 0" rpy="0 0 0"/>
            <mass value="1" />
            <inertia ixx="100" ixy="0" ixz="0" iyy="100" iyz="0" izz="100" />
        </inertial>
        <visual>
            <origin xyz="-0.31420841813043576 0 0" rpy="0 0 0"/>
            <geometry>
                <box size="0.6284168362608715 0.7992909767744105 0.9178386717564802" />
            </geometry>
            <material name="Green">
                <color rgba="0.25 0.76 0.50 1.0"/>
            </material>
        </visual>
        <collision>
            <origin xyz="-0.31420841813043576 0 0" rpy="0 0 0"/>
            <geometry>
                <box size="0.6284168362608715 0.7992909767744105 0.9178386717564802" />
            </geometry>
        </collision>
    </link>
    <joint name="Link2MinXLink0_Link2MinXLink1" type="revolute">
       <parent link="Link2MinXLink0"/>
       <child  link="Link2MinXLink1"/>
       <origin rpy="0 0 0" xyz="-0.6284168362608715 0 0" />
       <axis xyz="1 0 0"/>
       <limit effort="0.0" lower="-3.14159" upper="3.14159" velocity="0.0"/>
    </joint>
    <link name="Link2MinXLink1">
        <inertial>
            <origin xyz="-0.31420841813043576 0 0" rpy="0 0 0"/>
            <mass value="1" />
            <inertia ixx="100" ixy="0" ixz="0" iyy="100" iyz="0" izz="100" />
        </inertial>
        <visual>
            <origin xyz="-0.31420841813043576 0 0" rpy="0 0 0"/>
            <geometry>
                <box size="0.6284168362608715 0.7992909767744105 0.9178386717564802" />
            </geometry>
            <material name="Blue">
                <color rgba="0.01 0.54 1.0 1.0"/>
            </material>
        </visual>
        <collision>
            <origin xyz="-0.31420841813043576 0 0" rpy="0 0 0"/>
            <geometry>
                <box size="0.6284168362608715 0.7992909767744105 0.9178386717564802" />
            </geometry>
        </collision>
    </link>
    <joint name="Link2_Link2ZLink0" type="revolute">
       <parent link="Link2"/>
       <child  link="Link2ZLink0"/>
       <origin rpy="0 0 0" xyz="0 0.5025247989540937 0.2539811009267539" />
       <axis xyz="0 0 1"/>
       <limit effort="0.0" lower="-3.14159" upper="3.14159" velocity="0.0"/>
    </joint>
    <link name="Link2ZLink0">
        <inertial>
            <origin xyz="0 0 0.4174848226810118" rpy="0 0 0"/>
            <mass value="1" />
            <inertia ixx="100" ixy="0" ixz="0" iyy="100" iyz="0" izz="100" />
        </inertial>
        <visual>
            <origin xyz="0 0 0.4174848226810118" rpy="0 0 0"/>
            <geometry>
                <box size="0.6594740369894366 0.9948533891470371 0.8349696453620236" />
            </geometry>
            <material name="Blue">
                <color rgba="0.01 0.54 1.0 1.0"/>
            </material>
        </visual>
        <collision>
            <origin xyz="0 0 0.4174848226810118" rpy="0 0 0"/>
            <geometry>
                <box size="0.6594740369894366 0.9948533891470371 0.8349696453620236" />
            </geometry>
        </collision>
    </link>
</robot>