<robot name = "robot">
    <link name="Link0">
        <inertial>
            <origin xyz="0 0 0.3985020512553561" rpy="0 0 0"/>
            <mass value="1" />
            <inertia ixx="100" ixy="0" ixz="0" iyy="100" iyz="0" izz="100" />
        </inertial>
        <visual>
            <origin xyz="0 0 0.3985020512553561" rpy="0 0 0"/>
            <geometry>
                <box size="0.9389680298490857 0.39150720535749356 0.7970041025107122" />
            </geometry>
            <material name="Blue">
                <color rgba="0.01 0.54 1.0 1.0"/>
            </material>
        </visual>
        <collision>
            <origin xyz="0 0 0.3985020512553561" rpy="0 0 0"/>
            <geometry>
                <box size="0.9389680298490857 0.39150720535749356 0.7970041025107122" />
            </geometry>
        </collision>
    </link>
    <joint name="Link0_Link1" type="revolute">
       <parent link="Link0"/>
       <child  link="Link1"/>
       <origin rpy="0 0 0" xyz="0 0.19575360267874678 0.52083681818673" />
       <axis xyz="1 0 0"/>
       <limit effort="0.0" lower="-3.14159" upper="3.14159" velocity="0.0"/>
    </joint>
    <link name="Link1">
        <inertial>
            <origin xyz="0 0.3550857431677312 0" rpy="0 0 0"/>
            <mass value="1" />
            <inertia ixx="100" ixy="0" ixz="0" iyy="100" iyz="0" izz="100" />
        </inertial>
        <visual>
            <origin xyz="0 0.3550857431677312 0" rpy="0 0 0"/>
            <geometry>
                <box size="0.849619915693708 0.7101714863354625 0.8668539994261059" />
            </geometry>
            <material name="Blue">
                <color rgba="0.01 0.54 1.0 1.0"/>
            </material>
        </visual>
        <collision>
            <origin xyz="0 0.3550857431677312 0" rpy="0 0 0"/>
            <geometry>
                <box size="0.849619915693708 0.7101714863354625 0.8668539994261059" />
            </geometry>
        </collision>
    </link>
    <joint name="Link1_Link1XLink0" type="revolute">
       <parent link="Link1"/>
       <child  link="Link1XLink0"/>
       <origin rpy="0 0 0" xyz="0.424809957846854 0.3550857431677312 0" />
       <axis xyz="1 0 0"/>
       <limit effort="0.0" lower="-3.14159" upper="3.14159" velocity="0.0"/>
    </joint>
    <link name="Link1XLink0">
        <inertial>
            <origin xyz="0.5107076244928832 0 0" rpy="0 0 0"/>
            <mass value="1" />
            <inertia ixx="100" ixy="0" ixz="0" iyy="100" iyz="0" izz="100" />
        </inertial>
        <visual>
            <origin xyz="0.5107076244928832 0 0" rpy="0 0 0"/>
            <geometry>
                <box size="1.0214152489857664 0.7101714863354625 0.5205188573276438" />
            </geometry>
            <material name="Blue">
                <color rgba="0.01 0.54 1.0 1.0"/>
            </material>
        </visual>
        <collision>
            <origin xyz="0.5107076244928832 0 0" rpy="0 0 0"/>
            <geometry>
                <box size="1.0214152489857664 0.7101714863354625 0.5205188573276438" />
            </geometry>
        </collision>
    </link>
    <joint name="Link1_Link1MinXLink0" type="revolute">
       <parent link="Link1"/>
       <child  link="Link1MinXLink0"/>
       <origin rpy="0 0 0" xyz="-0.424809957846854 0.3550857431677312 0" />
       <axis xyz="1 0 0"/>
       <limit effort="0.0" lower="-3.14159" upper="3.14159" velocity="0.0"/>
    </joint>
    <link name="Link1MinXLink0">
        <inertial>
            <origin xyz="-0.22451981187127154 0 0" rpy="0 0 0"/>
            <mass value="1" />
            <inertia ixx="100" ixy="0" ixz="0" iyy="100" iyz="0" izz="100" />
        </inertial>
        <visual>
            <origin xyz="-0.22451981187127154 0 0" rpy="0 0 0"/>
            <geometry>
                <box size="0.4490396237425431 0.5473629271315353 0.48750752526340935" />
            </geometry>
            <material name="Green">
                <color rgba="0.25 0.76 0.50 1.0"/>
            </material>
        </visual>
        <collision>
            <origin xyz="-0.22451981187127154 0 0" rpy="0 0 0"/>
            <geometry>
                <box size="0.4490396237425431 0.5473629271315353 0.48750752526340935" />
            </geometry>
        </collision>
    </link>
    <joint name="Link1_Link2" type="revolute">
       <parent link="Link1"/>
       <child  link="Link2"/>
       <origin rpy="0 0 0" xyz="0 0.7101714863354625 0" />
       <axis xyz="1 0 0"/>
       <limit effort="0.0" lower="-3.14159" upper="3.14159" velocity="0.0"/>
    </joint>
    <link name="Link2">
        <inertial>
            <origin xyz="0 0.4105458079880479 0" rpy="0 0 0"/>
            <mass value="1" />
            <inertia ixx="100" ixy="0" ixz="0" iyy="100" iyz="0" izz="100" />
        </inertial>
        <visual>
            <origin xyz="0 0.4105458079880479 0" rpy="0 0 0"/>
            <geometry>
                <box size="0.9751908009039031 0.8210916159760958 1.04167363637346" />
            </geometry>
            <material name="Green">
                <color rgba="0.25 0.76 0.50 1.0"/>
            </material>
        </visual>
        <collision>
            <origin xyz="0 0.4105458079880479 0" rpy="0 0 0"/>
            <geometry>
                <box size="0.9751908009039031 0.8210916159760958 1.04167363637346" />
            </geometry>
        </collision>
    </link>
    <joint name="Link2_Link2XLink0" type="revolute">
       <parent link="Link2"/>
       <child  link="Link2XLink0"/>
       <origin rpy="0 0 0" xyz="0.48759540045195154 0.4105458079880479 0" />
       <axis xyz="1 0 0"/>
       <limit effort="0.0" lower="-3.14159" upper="3.14159" velocity="0.0"/>
    </joint>
    <link name="Link2XLink0">
        <inertial>
            <origin xyz="0.5328706494199018 0 0" rpy="0 0 0"/>
            <mass value="1" />
            <inertia ixx="100" ixy="0" ixz="0" iyy="100" iyz="0" izz="100" />
        </inertial>
        <visual>
            <origin xyz="0.5328706494199018 0 0" rpy="0 0 0"/>
            <geometry>
                <box size="1.0657412988398036 0.8210916159760958 0.5436847257302915" />
            </geometry>
            <material name="Green">
                <color rgba="0.25 0.76 0.50 1.0"/>
            </material>
        </visual>
        <collision>
            <origin xyz="0.5328706494199018 0 0" rpy="0 0 0"/>
            <geometry>
                <box size="1.0657412988398036 0.8210916159760958 0.5436847257302915" />
            </geometry>
        </collision>
    </link>
    <joint name="Link2_Link2MinXLink0" type="revolute">
       <parent link="Link2"/>
       <child  link="Link2MinXLink0"/>
       <origin rpy="0 0 0" xyz="-0.48759540045195154 0.4105458079880479 0" />
       <axis xyz="1 0 0"/>
       <limit effort="0.0" lower="-3.14159" upper="3.14159" velocity="0.0"/>
    </joint>
    <link name="Link2MinXLink0">
        <inertial>
            <origin xyz="-0.30595976660130947 0 0" rpy="0 0 0"/>
            <mass value="1" />
            <inertia ixx="100" ixy="0" ixz="0" iyy="100" iyz="0" izz="100" />
        </inertial>
        <visual>
            <origin xyz="-0.30595976660130947 0 0" rpy="0 0 0"/>
            <geometry>
                <box size="0.6119195332026189 0.656876652739679 0.6507062251215592" />
            </geometry>
            <material name="Blue">
                <color rgba="0.01 0.54 1.0 1.0"/>
            </material>
        </visual>
        <collision>
            <origin xyz="-0.30595976660130947 0 0" rpy="0 0 0"/>
            <geometry>
                <box size="0.6119195332026189 0.656876652739679 0.6507062251215592" />
            </geometry>
        </collision>
    </link>
</robot>